Workbook

Sheet Cash and runway, month 12 (Main
A1: Cash and runway, month 12 (Main vs Growth vs Downside)
A2: Cash and runway · Main Scenario
A4: Variable / dimension | B4: 2027-09 | C4: 2027-09 > Growth | D4: 2027-09 > Downside
A5: Gross profit (USD) | B5: =SUM('Model inputs'!N10,'Model inputs'!N11) -> 705.52776 | C5: =SUM('Model inputs'!N16,'Model inputs'!N17) -> 1143.45 | D5: =SUM('Model inputs'!N13,'Model inputs'!N14) -> 305.91145
A6: Other fixed costs (USD) | B6: =IF('Model inputs'!O24="","",'Model inputs'!O24) -> 50 | C6: =IF('Model inputs'!O26="","",'Model inputs'!O26) -> 50 | D6: =IF('Model inputs'!O25="","",'Model inputs'!O25) -> 50
A7: Net cash flow (USD) | B7: ='Cash and runway, month 12 (Main'!B5-'Cash and runway, month 12 (Main'!B6 -> 655.52776 | C7: ='Cash and runway, month 12 (Main'!C5-'Cash and runway, month 12 (Main'!C6 -> 1093.45 | D7: ='Cash and runway, month 12 (Main'!D5-'Cash and runway, month 12 (Main'!D6 -> 255.91145
A8: Ending cash (USD) | B8: ='Cash and runway (monthly)'!L8+'Cash and runway, month 12 (Main'!B7 -> 8275.9599 | C8: ='Model inputs'!M8+'Cash and runway, month 12 (Main'!C7 -> 11089.106 | D8: ='Model inputs'!M7+'Cash and runway, month 12 (Main'!D7 -> 4757.3516
A9: Runway in months (0 = not burning cash) | B9: =IF(IF(IF(ISERROR('Cash and runway, month 12 (Main'!B7<0),'Cash and runway, month 12 (Main'!B7<0,IF('Cash and runway, month 12 (Main'!B7="","",'Cash and runway, month 12 (Main'!B7<0))="",FALSE,IF(ISERROR('Cash and runway, month 12 (Main'!B7<0),'Cash and runway, month 12 (Main'!B7<0,IF('Cash and runway, month 12 (Main'!B7="","",'Cash and runway, month 12 (Main'!B7<0))),'Cash and runway, month 12 (Main'!B8/-'Cash and runway, month 12 (Main'!B7,0) -> 0 | C9: =IF(IF(IF(ISERROR('Cash and runway, month 12 (Main'!C7<0),'Cash and runway, month 12 (Main'!C7<0,IF('Cash and runway, month 12 (Main'!C7="","",'Cash and runway, month 12 (Main'!C7<0))="",FALSE,IF(ISERROR('Cash and runway, month 12 (Main'!C7<0),'Cash and runway, month 12 (Main'!C7<0,IF('Cash and runway, month 12 (Main'!C7="","",'Cash and runway, month 12 (Main'!C7<0))),'Cash and runway, month 12 (Main'!C8/-'Cash and runway, month 12 (Main'!C7,0) -> 0 | D9: =IF(IF(IF(ISERROR('Cash and runway, month 12 (Main'!D7<0),'Cash and runway, month 12 (Main'!D7<0,IF('Cash and runway, month 12 (Main'!D7="","",'Cash and runway, month 12 (Main'!D7<0))="",FALSE,IF(ISERROR('Cash and runway, month 12 (Main'!D7<0),'Cash and runway, month 12 (Main'!D7<0,IF('Cash and runway, month 12 (Main'!D7="","",'Cash and runway, month 12 (Main'!D7<0))),'Cash and runway, month 12 (Main'!D8/-'Cash and runway, month 12 (Main'!D7,0) -> 0

Sheet Cash and runway (monthly)
A1: Cash and runway (monthly)
A2: Cash and runway · Main Scenario
A4: Variable / dimension | B4: 2026-10 | C4: 2026-11 | D4: 2026-12 | E4: 2027-01 | F4: 2027-02 | G4: 2027-03 | H4: 2027-04 | I4: 2027-05 | J4: 2027-06 | K4: 2027-07 | L4: 2027-08 | M4: 2027-09
A5: Gross profit (USD) | B5: =SUM('Model inputs'!C10,'Model inputs'!C11) -> 409.4947 | C5: =SUM('Model inputs'!D10,'Model inputs'!D11) -> 445.84389 | D5: =SUM('Model inputs'!E10,'Model inputs'!E11) -> 479.87065 | E5: =SUM('Model inputs'!F10,'Model inputs'!F11) -> 511.74321 | F5: =SUM('Model inputs'!G10,'Model inputs'!G11) -> 541.61686 | G5: =SUM('Model inputs'!H10,'Model inputs'!H11) -> 569.63499 | H5: =SUM('Model inputs'!I10,'Model inputs'!I11) -> 595.93001 | I5: =SUM('Model inputs'!J10,'Model inputs'!J11) -> 620.62422 | ... M5: =SUM('Model inputs'!N10,'Model inputs'!N11) -> 705.52776
A6: Other fixed costs (USD) | B6: =IF('Model inputs'!O24="","",'Model inputs'!O24) -> 50 | C6: =IF('Model inputs'!O24="","",'Model inputs'!O24) -> 50 | D6: =IF('Model inputs'!O24="","",'Model inputs'!O24) -> 50 | E6: =IF('Model inputs'!O24="","",'Model inputs'!O24) -> 50 | F6: =IF('Model inputs'!O24="","",'Model inputs'!O24) -> 50 | G6: =IF('Model inputs'!O24="","",'Model inputs'!O24) -> 50 | H6: =IF('Model inputs'!O24="","",'Model inputs'!O24) -> 50 | I6: =IF('Model inputs'!O24="","",'Model inputs'!O24) -> 50 | J6: =IF('Model inputs'!O24="","",'Model inputs'!O24) -> 50 | K6: =IF('Model inputs'!O24="","",'Model inputs'!O24) -> 50 | L6: =IF('Model inputs'!O24="","",'Model inputs'!O24) -> 50 | M6: =IF('Model inputs'!O24="","",'Model inputs'!O24) -> 50
A7: Net cash flow (USD) | B7: ='Cash and runway (monthly)'!B5-'Cash and runway (monthly)'!B6 -> 359.4947 | C7: ='Cash and runway (monthly)'!C5-'Cash and runway (monthly)'!C6 -> 395.84389 | D7: ='Cash and runway (monthly)'!D5-'Cash and runway (monthly)'!D6 -> 429.87065 | E7: ='Cash and runway (monthly)'!E5-'Cash and runway (monthly)'!E6 -> 461.74321 | F7: ='Cash and runway (monthly)'!F5-'Cash and runway (monthly)'!F6 -> 491.61686 | G7: ='Cash and runway (monthly)'!G5-'Cash and runway (monthly)'!G6 -> 519.63499 | H7: ='Cash and runway (monthly)'!H5-'Cash and runway (monthly)'!H6 -> 545.93001 | I7: ='Cash and runway (monthly)'!I5-'Cash and runway (monthly)'!I6 -> 570.62422 | ... M7: ='Cash and runway (monthly)'!M5-'Cash and runway (monthly)'!M6 -> 655.52776
A8: Ending cash (USD) | B8: ='Model inputs'!B6+'Cash and runway (monthly)'!B7 -> 2359.4947 | C8: ='Cash and runway (monthly)'!B8+'Cash and runway (monthly)'!C7 -> 2755.3386 | D8: ='Cash and runway (monthly)'!C8+'Cash and runway (monthly)'!D7 -> 3185.2092 | E8: ='Cash and runway (monthly)'!D8+'Cash and runway (monthly)'!E7 -> 3646.9524 | F8: ='Cash and runway (monthly)'!E8+'Cash and runway (monthly)'!F7 -> 4138.5693 | G8: ='Cash and runway (monthly)'!F8+'Cash and runway (monthly)'!G7 -> 4658.2043 | H8: ='Cash and runway (monthly)'!G8+'Cash and runway (monthly)'!H7 -> 5204.1343 | I8: ='Cash and runway (monthly)'!H8+'Cash and runway (monthly)'!I7 -> 5774.7585 | J8: ='Cash and runway (monthly)'!I8+'Cash and runway (monthly)'!J7 -> 6368.5891 | ... M8: ='Cash and runway (monthly)'!L8+'Cash and runway (monthly)'!M7 -> 8275.9599
A9: Runway in months (0 = not burning cash) | B9: =IF(IF(IF(ISERROR('Cash and runway (monthly)'!B7<0),'Cash and runway (monthly)'!B7<0,IF('Cash and runway (monthly)'!B7="","",'Cash and runway (monthly)'!B7<0))="",FALSE,IF(ISERROR('Cash and runway (monthly)'!B7<0),'Cash and runway (monthly)'!B7<0,IF('Cash and runway (monthly)'!B7="","",'Cash and runway (monthly)'!B7<0))),'Cash and runway (monthly)'!B8/-'Cash and runway (monthly)'!B7,0) -> 0 | C9: =IF(IF(IF(ISERROR('Cash and runway (monthly)'!C7<0),'Cash and runway (monthly)'!C7<0,IF('Cash and runway (monthly)'!C7="","",'Cash and runway (monthly)'!C7<0))="",FALSE,IF(ISERROR('Cash and runway (monthly)'!C7<0),'Cash and runway (monthly)'!C7<0,IF('Cash and runway (monthly)'!C7="","",'Cash and runway (monthly)'!C7<0))),'Cash and runway (monthly)'!C8/-'Cash and runway (monthly)'!C7,0) -> 0 | D9: =IF(IF(IF(ISERROR('Cash and runway (monthly)'!D7<0),'Cash and runway (monthly)'!D7<0,IF('Cash and runway (monthly)'!D7="","",'Cash and runway (monthly)'!D7<0))="",FALSE,IF(ISERROR('Cash and runway (monthly)'!D7<0),'Cash and runway (monthly)'!D7<0,IF('Cash and runway (monthly)'!D7="","",'Cash and runway (monthly)'!D7<0))),'Cash and runway (monthly)'!D8/-'Cash and runway (monthly)'!D7,0) -> 0 | E9: =IF(IF(IF(ISERROR('Cash and runway (monthly)'!E7<0),'Cash and runway (monthly)'!E7<0,IF('Cash and runway (monthly)'!E7="","",'Cash and runway (monthly)'!E7<0))="",FALSE,IF(ISERROR('Cash and runway (monthly)'!E7<0),'Cash and runway (monthly)'!E7<0,IF('Cash and runway (monthly)'!E7="","",'Cash and runway (monthly)'!E7<0))),'Cash and runway (monthly)'!E8/-'Cash and runway (monthly)'!E7,0) -> 0 | F9: =IF(IF(IF(ISERROR('Cash and runway (monthly)'!F7<0),'Cash and runway (monthly)'!F7<0,IF('Cash and runway (monthly)'!F7="","",'Cash and runway (monthly)'!F7<0))="",FALSE,IF(ISERROR('Cash and runway (monthly)'!F7<0),'Cash and runway (monthly)'!F7<0,IF('Cash and runway (monthly)'!F7="","",'Cash and runway (monthly)'!F7<0))),'Cash and runway (monthly)'!F8/-'Cash and runway (monthly)'!F7,0) -> 0 | G9: =IF(IF(IF(ISERROR('Cash and runway (monthly)'!G7<0),'Cash and runway (monthly)'!G7<0,IF('Cash and runway (monthly)'!G7="","",'Cash and runway (monthly)'!G7<0))="",FALSE,IF(ISERROR('Cash and runway (monthly)'!G7<0),'Cash and runway (monthly)'!G7<0,IF('Cash and runway (monthly)'!G7="","",'Cash and runway (monthly)'!G7<0))),'Cash and runway (monthly)'!G8/-'Cash and runway (monthly)'!G7,0) -> 0 | H9: =IF(IF(IF(ISERROR('Cash and runway (monthly)'!H7<0),'Cash and runway (monthly)'!H7<0,IF('Cash and runway (monthly)'!H7="","",'Cash and runway (monthly)'!H7<0))="",FALSE,IF(ISERROR('Cash and runway (monthly)'!H7<0),'Cash and runway (monthly)'!H7<0,IF('Cash and runway (monthly)'!H7="","",'Cash and runway (monthly)'!H7<0))),'Cash and runway (monthly)'!H8/-'Cash and runway (monthly)'!H7,0) -> 0 | I9: =IF(IF(IF(ISERROR('Cash and runway (monthly)'!I7<0),'Cash and runway (monthly)'!I7<0,IF('Cash and runway (monthly)'!I7="","",'Cash and runway (monthly)'!I7<0))="",FALSE,IF(ISERROR('Cash and runway (monthly)'!I7<0),'Cash and runway (monthly)'!I7<0,IF('Cash and runway (monthly)'!I7="","",'Cash and runway (monthly)'!I7<0))),'Cash and runway (monthly)'!I8/-'Cash and runway (monthly)'!I7,0) -> 0 | ... M9: =IF(IF(IF(ISERROR('Cash and runway (monthly)'!M7<0),'Cash and runway (monthly)'!M7<0,IF('Cash and runway (monthly)'!M7="","",'Cash and runway (monthly)'!M7<0))="",FALSE,IF(ISERROR('Cash and runway (monthly)'!M7<0),'Cash and runway (monthly)'!M7<0,IF('Cash and runway (monthly)'!M7="","",'Cash and runway (monthly)'!M7<0))),'Cash and runway (monthly)'!M8/-'Cash and runway (monthly)'!M7,0) -> 0

Sheet Model inputs
A1: Model inputs
A2: Integration values are aggregated snapshots; raw source records are not included.
A4: Variables
A5: Variable / segment | B5: 2026-09 | C5: 2026-10 | D5: 2026-11 | E5: 2026-12 | F5: 2027-01 | G5: 2027-02 | H5: 2027-03 | I5: 2027-04 | J5: 2027-05 | K5: 2027-06 | L5: 2027-07 | M5: 2027-08 | N5: 2027-09 | O5: Value
A6: Ending cash (USD) · Main Scenario | B6: =IF('Model inputs'!O45="","",'Model inputs'!O45) -> 2000 | C6: ='Model inputs'!B6+'Model inputs'!C18 -> 2359.4947 | D6: ='Model inputs'!C6+'Model inputs'!D18 -> 2755.3386 | E6: ='Model inputs'!D6+'Model inputs'!E18 -> 3185.2092 | F6: ='Model inputs'!E6+'Model inputs'!F18 -> 3646.9524 | G6: ='Model inputs'!F6+'Model inputs'!G18 -> 4138.5693 | H6: ='Model inputs'!G6+'Model inputs'!H18 -> 4658.2043 | I6: ='Model inputs'!H6+'Model inputs'!I18 -> 5204.1343 | J6: ='Model inputs'!I6+'Model inputs'!J18 -> 5774.7585 | ... N6: ='Model inputs'!M6+'Model inputs'!N18 -> 8275.9599
A7: Ending cash (USD) · Downside | B7: =IF('Model inputs'!O46="","",'Model inputs'!O46) -> 2000 | C7: ='Model inputs'!B7+'Model inputs'!C19 -> 2190.4742 | D7: ='Model inputs'!C7+'Model inputs'!D19 -> 2391.3502 | E7: ='Model inputs'!D7+'Model inputs'!E19 -> 2601.3262 | F7: ='Model inputs'!E7+'Model inputs'!F19 -> 2819.2807 | G7: ='Model inputs'!F7+'Model inputs'!G19 -> 3044.2454 | H7: ='Model inputs'!G7+'Model inputs'!H19 -> 3275.3837 | I7: ='Model inputs'!H7+'Model inputs'!I19 -> 3511.9715 | J7: ='Model inputs'!I7+'Model inputs'!J19 -> 3753.3814 | ... N7: ='Model inputs'!M7+'Model inputs'!N19 -> 4757.3516
A8: Ending cash (USD) · Growth | B8: =IF('Model inputs'!O47="","",'Model inputs'!O47) -> 2000 | C8: ='Model inputs'!B8+'Model inputs'!C20 -> 2345.394 | D8: ='Model inputs'!C8+'Model inputs'!D20 -> 2781.9125 | E8: ='Model inputs'!D8+'Model inputs'!E20 -> 3303.8824 | F8: ='Model inputs'!E8+'Model inputs'!F20 -> 3906.0362 | G8: ='Model inputs'!F8+'Model inputs'!G20 -> 4583.4807 | H8: ='Model inputs'!G8+'Model inputs'!H20 -> 5331.6683 | I8: ='Model inputs'!H8+'Model inputs'!I20 -> 6146.3713 | J8: ='Model inputs'!I8+'Model inputs'!J20 -> 7023.657 | ... N8: ='Model inputs'!M8+'Model inputs'!N20 -> 11089.106
A9: Gross profit (USD) | B9: =SUM('Model inputs'!B10,'Model inputs'!B11) -> 0 | C9: =SUM('Model inputs'!C10,'Model inputs'!C11) -> 409.4947 | D9: =SUM('Model inputs'!D10,'Model inputs'!D11) -> 445.84389 | E9: =SUM('Model inputs'!E10,'Model inputs'!E11) -> 479.87065 | F9: =SUM('Model inputs'!F10,'Model inputs'!F11) -> 511.74321 | G9: =SUM('Model inputs'!G10,'Model inputs'!G11) -> 541.61686 | H9: =SUM('Model inputs'!H10,'Model inputs'!H11) -> 569.63499 | I9: =SUM('Model inputs'!I10,'Model inputs'!I11) -> 595.93001 | ... N9: =SUM('Model inputs'!N10,'Model inputs'!N11) -> 705.52776
A10: Gross profit (USD) > Classroom | B10: =0 -> 0 | C10: ='Model inputs'!C37-'Model inputs'!C28 -> 172.08938 | D10: ='Model inputs'!D37-'Model inputs'!D28 -> 184.00241 | E10: ='Model inputs'!E37-'Model inputs'!E28 -> 195.5051 | F10: ='Model inputs'!F37-'Model inputs'!F28 -> 206.6235 | G10: ='Model inputs'!G37-'Model inputs'!G28 -> 217.37851 | H10: ='Model inputs'!H37-'Model inputs'!H28 -> 227.78766 | I10: ='Model inputs'!I37-'Model inputs'!I28 -> 237.86612 | J10: ='Model inputs'!J37-'Model inputs'!J28 -> 247.62738 | ... N10: ='Model inputs'!N37-'Model inputs'!N28 -> 283.73132
A11: Gross profit (USD) > Household | B11: =0 -> 0 | C11: ='Model inputs'!C38-'Model inputs'!C29 -> 237.40531 | D11: ='Model inputs'!D38-'Model inputs'!D29 -> 261.84148 | E11: ='Model inputs'!E38-'Model inputs'!E29 -> 284.36555 | F11: ='Model inputs'!F38-'Model inputs'!F29 -> 305.11971 | G11: ='Model inputs'!G38-'Model inputs'!G29 -> 324.23834 | H11: ='Model inputs'!H38-'Model inputs'!H29 -> 341.84733 | I11: ='Model inputs'!I38-'Model inputs'!I29 -> 358.06389 | J11: ='Model inputs'!J38-'Model inputs'!J29 -> 372.99684 | ... N11: ='Model inputs'!N38-'Model inputs'!N29 -> 421.79644
A12: Gross profit (USD) | B12: =SUM('Model inputs'!B13,'Model inputs'!B14) -> 0 | C12: =SUM('Model inputs'!C13,'Model inputs'!C14) -> 240.47424 | D12: =SUM('Model inputs'!D13,'Model inputs'!D14) -> 250.87592 | E12: =SUM('Model inputs'!E13,'Model inputs'!E14) -> 259.97609 | F12: =SUM('Model inputs'!F13,'Model inputs'!F14) -> 267.95445 | G12: =SUM('Model inputs'!G13,'Model inputs'!G14) -> 274.96468 | H12: =SUM('Model inputs'!H13,'Model inputs'!H14) -> 281.13828 | I12: =SUM('Model inputs'!I13,'Model inputs'!I14) -> 286.58785 | ... N12: =SUM('Model inputs'!N13,'Model inputs'!N14) -> 305.91145
A13: Gross profit (USD) > Classroom | B13: ='Model inputs'!B10 -> 0 | C13: ='Model inputs'!C40-'Model inputs'!C31 -> 66.849964 | D13: ='Model inputs'!D40-'Model inputs'!D31 -> 69.750873 | E13: ='Model inputs'!E40-'Model inputs'!E31 -> 72.454894 | F13: ='Model inputs'!F40-'Model inputs'!F31 -> 74.979082 | G13: ='Model inputs'!G40-'Model inputs'!G31 -> 77.33806 | H13: ='Model inputs'!H40-'Model inputs'!H31 -> 79.544609 | I13: ='Model inputs'!I40-'Model inputs'!I31 -> 81.610057 | J13: ='Model inputs'!J40-'Model inputs'!J31 -> 83.544561 | ... N13: ='Model inputs'!N40-'Model inputs'!N31 -> 90.145049
A14: Gross profit (USD) > Household | B14: ='Model inputs'!B11 -> 0 | C14: ='Model inputs'!C41-'Model inputs'!C32 -> 173.62428 | D14: ='Model inputs'!D41-'Model inputs'!D32 -> 181.12505 | E14: ='Model inputs'!E41-'Model inputs'!E32 -> 187.52119 | F14: ='Model inputs'!F41-'Model inputs'!F32 -> 192.97537 | G14: ='Model inputs'!G41-'Model inputs'!G32 -> 197.62662 | H14: ='Model inputs'!H41-'Model inputs'!H32 -> 201.59367 | I14: ='Model inputs'!I41-'Model inputs'!I32 -> 204.97779 | J14: ='Model inputs'!J41-'Model inputs'!J32 -> 207.86531 | ... N14: ='Model inputs'!N41-'Model inputs'!N32 -> 215.7664
A15: Gross profit (USD) | B15: =SUM('Model inputs'!B16,'Model inputs'!B17) -> 0 | C15: =SUM('Model inputs'!C16,'Model inputs'!C17) -> 395.39405 | D15: =SUM('Model inputs'!D16,'Model inputs'!D17) -> 486.51844 | E15: =SUM('Model inputs'!E16,'Model inputs'!E17) -> 571.96992 | F15: =SUM('Model inputs'!F16,'Model inputs'!F17) -> 652.1538 | G15: =SUM('Model inputs'!G16,'Model inputs'!G17) -> 727.44445 | H15: =SUM('Model inputs'!H16,'Model inputs'!H17) -> 798.18766 | I15: =SUM('Model inputs'!I16,'Model inputs'!I17) -> 864.70297 | ... N15: =SUM('Model inputs'!N16,'Model inputs'!N17) -> 1143.45
A16: Gross profit (USD) > Classroom | B16: ='Model inputs'!B10 -> 0 | C16: ='Model inputs'!C43-'Model inputs'!C34 -> 144.33904 | D16: ='Model inputs'!D43-'Model inputs'!D34 -> 176.76625 | E16: ='Model inputs'!E43-'Model inputs'!E34 -> 208.14712 | F16: ='Model inputs'!F43-'Model inputs'!F34 -> 238.54454 | G16: ='Model inputs'!G43-'Model inputs'!G34 -> 268.0037 | H16: ='Model inputs'!H43-'Model inputs'!H34 -> 296.56141 | I16: ='Model inputs'!I43-'Model inputs'!I34 -> 324.2499 | J16: ='Model inputs'!J43-'Model inputs'!J34 -> 351.09856 | ... N16: ='Model inputs'!N43-'Model inputs'!N34 -> 450.62206
A17: Gross profit (USD) > Household | B17: ='Model inputs'!B11 -> 0 | C17: ='Model inputs'!C44-'Model inputs'!C35 -> 251.05501 | D17: ='Model inputs'!D44-'Model inputs'!D35 -> 309.75219 | E17: ='Model inputs'!E44-'Model inputs'!E35 -> 363.8228 | F17: ='Model inputs'!F44-'Model inputs'!F35 -> 413.60926 | G17: ='Model inputs'!G44-'Model inputs'!G35 -> 459.44075 | H17: ='Model inputs'!H44-'Model inputs'!H35 -> 501.62625 | I17: ='Model inputs'!I44-'Model inputs'!I35 -> 540.45307 | J17: ='Model inputs'!J44-'Model inputs'!J35 -> 576.18711 | ... N17: ='Model inputs'!N44-'Model inputs'!N35 -> 692.82791
A18: Net cash flow (USD) · Main Scenario | B18: 0 | C18: ='Model inputs'!C9-'Model inputs'!C21 -> 359.4947 | D18: ='Model inputs'!D9-'Model inputs'!D21 -> 395.84389 | E18: ='Model inputs'!E9-'Model inputs'!E21 -> 429.87065 | F18: ='Model inputs'!F9-'Model inputs'!F21 -> 461.74321 | G18: ='Model inputs'!G9-'Model inputs'!G21 -> 491.61686 | H18: ='Model inputs'!H9-'Model inputs'!H21 -> 519.63499 | I18: ='Model inputs'!I9-'Model inputs'!I21 -> 545.93001 | J18: ='Model inputs'!J9-'Model inputs'!J21 -> 570.62422 | ... N18: ='Model inputs'!N9-'Model inputs'!N21 -> 655.52776
A19: Net cash flow (USD) · Downside | B19: 0 | C19: ='Model inputs'!C12-'Model inputs'!C22 -> 190.47424 | D19: ='Model inputs'!D12-'Model inputs'!D22 -> 200.87592 | E19: ='Model inputs'!E12-'Model inputs'!E22 -> 209.97609 | F19: ='Model inputs'!F12-'Model inputs'!F22 -> 217.95445 | G19: ='Model inputs'!G12-'Model inputs'!G22 -> 224.96468 | H19: ='Model inputs'!H12-'Model inputs'!H22 -> 231.13828 | I19: ='Model inputs'!I12-'Model inputs'!I22 -> 236.58785 | J19: ='Model inputs'!J12-'Model inputs'!J22 -> 241.40988 | ... N19: ='Model inputs'!N12-'Model inputs'!N22 -> 255.91145
A20: Net cash flow (USD) · Growth | B20: 0 | C20: ='Model inputs'!C15-'Model inputs'!C23 -> 345.39405 | D20: ='Model inputs'!D15-'Model inputs'!D23 -> 436.51844 | E20: ='Model inputs'!E15-'Model inputs'!E23 -> 521.96992 | F20: ='Model inputs'!F15-'Model inputs'!F23 -> 602.1538 | G20: ='Model inputs'!G15-'Model inputs'!G23 -> 677.44445 | H20: ='Model inputs'!H15-'Model inputs'!H23 -> 748.18766 | I20: ='Model inputs'!I15-'Model inputs'!I23 -> 814.70297 | J20: ='Model inputs'!J15-'Model inputs'!J23 -> 877.28566 | ... N20: ='Model inputs'!N15-'Model inputs'!N23 -> 1093.45
A21: Other fixed costs (USD) · Main Scenario | B21: 0 | C21: =IF('Model inputs'!O24="","",'Model inputs'!O24) -> 50 | D21: =IF('Model inputs'!O24="","",'Model inputs'!O24) -> 50 | E21: =IF('Model inputs'!O24="","",'Model inputs'!O24) -> 50 | F21: =IF('Model inputs'!O24="","",'Model inputs'!O24) -> 50 | G21: =IF('Model inputs'!O24="","",'Model inputs'!O24) -> 50 | H21: =IF('Model inputs'!O24="","",'Model inputs'!O24) -> 50 | I21: =IF('Model inputs'!O24="","",'Model inputs'!O24) -> 50 | J21: =IF('Model inputs'!O24="","",'Model inputs'!O24) -> 50 | K21: =IF('Model inputs'!O24="","",'Model inputs'!O24) -> 50 | L21: =IF('Model inputs'!O24="","",'Model inputs'!O24) -> 50 | M21: =IF('Model inputs'!O24="","",'Model inputs'!O24) -> 50 | N21: =IF('Model inputs'!O24="","",'Model inputs'!O24) -> 50
A22: Other fixed costs (USD) · Downside | B22: 0 | C22: =IF('Model inputs'!O25="","",'Model inputs'!O25) -> 50 | D22: =IF('Model inputs'!O25="","",'Model inputs'!O25) -> 50 | E22: =IF('Model inputs'!O25="","",'Model inputs'!O25) -> 50 | F22: =IF('Model inputs'!O25="","",'Model inputs'!O25) -> 50 | G22: =IF('Model inputs'!O25="","",'Model inputs'!O25) -> 50 | H22: =IF('Model inputs'!O25="","",'Model inputs'!O25) -> 50 | I22: =IF('Model inputs'!O25="","",'Model inputs'!O25) -> 50 | J22: =IF('Model inputs'!O25="","",'Model inputs'!O25) -> 50 | K22: =IF('Model inputs'!O25="","",'Model inputs'!O25) -> 50 | L22: =IF('Model inputs'!O25="","",'Model inputs'!O25) -> 50 | M22: =IF('Model inputs'!O25="","",'Model inputs'!O25) -> 50 | N22: =IF('Model inputs'!O25="","",'Model inputs'!O25) -> 50
A23: Other fixed costs (USD) · Growth | B23: 0 | C23: =IF('Model inputs'!O26="","",'Model inputs'!O26) -> 50 | D23: =IF('Model inputs'!O26="","",'Model inputs'!O26) -> 50 | E23: =IF('Model inputs'!O26="","",'Model inputs'!O26) -> 50 | F23: =IF('Model inputs'!O26="","",'Model inputs'!O26) -> 50 | G23: =IF('Model inputs'!O26="","",'Model inputs'!O26) -> 50 | H23: =IF('Model inputs'!O26="","",'Model inputs'!O26) -> 50 | I23: =IF('Model inputs'!O26="","",'Model inputs'!O26) -> 50 | J23: =IF('Model inputs'!O26="","",'Model inputs'!O26) -> 50 | K23: =IF('Model inputs'!O26="","",'Model inputs'!O26) -> 50 | L23: =IF('Model inputs'!O26="","",'Model inputs'!O26) -> 50 | M23: =IF('Model inputs'!O26="","",'Model inputs'!O26) -> 50 | N23: =IF('Model inputs'!O26="","",'Model inputs'!O26) -> 50
A24: Other fixed costs per month (USD, assumed) · Main Scenario | O24: =50 -> 50
A25: Other fixed costs per month (USD, assumed) · Downside | O25: ='Model inputs'!O24 -> 50
A26: Other fixed costs per month (USD, assumed) · Growth | O26: ='Model inputs'!O24 -> 50
A27: Infra and inference (USD) | B27: =SUM('Model inputs'!B28,'Model inputs'!B29) -> 0 | C27: =SUM('Model inputs'!C28,'Model inputs'!C29) -> 213.9573 | D27: =SUM('Model inputs'!D28,'Model inputs'!D29) -> 228.16695 | E27: =SUM('Model inputs'!E28,'Model inputs'!E29) -> 241.63887 | F27: =SUM('Model inputs'!F28,'Model inputs'!F29) -> 254.42012 | G27: =SUM('Model inputs'!G28,'Model inputs'!G29) -> 266.55433 | H27: =SUM('Model inputs'!H28,'Model inputs'!H29) -> 278.082 | I27: =SUM('Model inputs'!I28,'Model inputs'!I29) -> 289.04074 | ... N27: =SUM('Model inputs'!N28,'Model inputs'!N29) -> 336.43963
A28: Infra and inference (USD) > Classroom | B28: =0 -> 0 | C28: ='Model inputs'!C58+'Model inputs'!C49 -> 138.21062 | D28: ='Model inputs'!D58+'Model inputs'!D49 -> 145.98859 | E28: ='Model inputs'!E58+'Model inputs'!E49 -> 153.58617 | F28: ='Model inputs'!F58+'Model inputs'!F49 -> 160.99503 | G28: ='Model inputs'!G58+'Model inputs'!G49 -> 168.21146 | H28: ='Model inputs'!H58+'Model inputs'!H49 -> 175.23462 | I28: ='Model inputs'!I58+'Model inputs'!I49 -> 182.06549 | J28: ='Model inputs'!J58+'Model inputs'!J49 -> 188.70628 | ... N28: ='Model inputs'!N58+'Model inputs'!N49 -> 213.43535
A29: Infra and inference (USD) > Household | B29: =0 -> 0 | C29: ='Model inputs'!C59+'Model inputs'!C50 -> 75.746686 | D29: ='Model inputs'!D59+'Model inputs'!D50 -> 82.178358 | E29: ='Model inputs'!E59+'Model inputs'!E50 -> 88.052704 | F29: ='Model inputs'!F59+'Model inputs'!F50 -> 93.425087 | G29: ='Model inputs'!G59+'Model inputs'!G50 -> 98.342866 | H29: ='Model inputs'!H59+'Model inputs'!H50 -> 102.84738 | I29: ='Model inputs'!I59+'Model inputs'!I50 -> 106.97524 | J29: ='Model inputs'!J59+'Model inputs'!J50 -> 110.75917 | ... N29: ='Model inputs'!N59+'Model inputs'!N50 -> 123.00428
A30: Infra and inference (USD) | B30: =SUM('Model inputs'!B31,'Model inputs'!B32) -> 0 | C30: =SUM('Model inputs'!C31,'Model inputs'!C32) -> 354.70576 | D30: =SUM('Model inputs'!D31,'Model inputs'!D32) -> 367.09108 | E30: =SUM('Model inputs'!E31,'Model inputs'!E32) -> 378.34122 | F30: =SUM('Model inputs'!F31,'Model inputs'!F32) -> 388.5831 | G30: =SUM('Model inputs'!G31,'Model inputs'!G32) -> 397.92721 | H30: =SUM('Model inputs'!H31,'Model inputs'!H32) -> 406.4699 | I30: =SUM('Model inputs'!I31,'Model inputs'!I32) -> 414.29536 | ... N30: =SUM('Model inputs'!N31,'Model inputs'!N32) -> 444.9537
A31: Infra and inference (USD) > Classroom | B31: ='Model inputs'!B28 -> 0 | C31: ='Model inputs'!C61+'Model inputs'!C52 -> 234.75004 | D31: ='Model inputs'!D61+'Model inputs'!D52 -> 242.75313 | E31: ='Model inputs'!E61+'Model inputs'!E52 -> 250.29887 | F31: ='Model inputs'!F61+'Model inputs'!F52 -> 257.40945 | G31: ='Model inputs'!G61+'Model inputs'!G52 -> 264.10716 | H31: ='Model inputs'!H61+'Model inputs'!H52 -> 270.4139 | I31: ='Model inputs'!I61+'Model inputs'!I52 -> 276.35094 | J31: ='Model inputs'!J61+'Model inputs'!J52 -> 281.93878 | ... N31: ='Model inputs'!N61+'Model inputs'!N52 -> 301.17702
A32: Infra and inference (USD) > Household | B32: ='Model inputs'!B29 -> 0 | C32: ='Model inputs'!C62+'Model inputs'!C53 -> 119.95572 | D32: ='Model inputs'!D62+'Model inputs'!D53 -> 124.33795 | E32: ='Model inputs'!E62+'Model inputs'!E53 -> 128.04236 | F32: ='Model inputs'!F62+'Model inputs'!F53 -> 131.17365 | G32: ='Model inputs'!G62+'Model inputs'!G53 -> 133.82005 | H32: ='Model inputs'!H62+'Model inputs'!H53 -> 136.056 | I32: ='Model inputs'!I62+'Model inputs'!I53 -> 137.94442 | J32: ='Model inputs'!J62+'Model inputs'!J53 -> 139.53857 | ... N32: ='Model inputs'!N62+'Model inputs'!N53 -> 143.77667
A33: Infra and inference (USD) | B33: =SUM('Model inputs'!B34,'Model inputs'!B35) -> 0 | C33: =SUM('Model inputs'!C34,'Model inputs'!C35) -> 341.97795 | D33: =SUM('Model inputs'!D34,'Model inputs'!D35) -> 409.1188 | E33: =SUM('Model inputs'!E34,'Model inputs'!E35) -> 473.06889 | F33: =SUM('Model inputs'!F34,'Model inputs'!F35) -> 534.01808 | G33: =SUM('Model inputs'!G34,'Model inputs'!G35) -> 592.14297 | H33: =SUM('Model inputs'!H34,'Model inputs'!H35) -> 647.60797 | I33: =SUM('Model inputs'!I34,'Model inputs'!I35) -> 700.56616 | ... N33: =SUM('Model inputs'!N34,'Model inputs'!N35) -> 932.42337
A34: Infra and inference (USD) > Classroom | B34: ='Model inputs'!B28 -> 0 | C34: ='Model inputs'!C64+'Model inputs'!C55 -> 223.96096 | D34: ='Model inputs'!D64+'Model inputs'!D55 -> 267.48475 | E34: ='Model inputs'!E64+'Model inputs'!E55 -> 309.77635 | F34: ='Model inputs'!F64+'Model inputs'!F55 -> 350.84122 | G34: ='Model inputs'!G64+'Model inputs'!G55 -> 390.70049 | H34: ='Model inputs'!H64+'Model inputs'!H55 -> 429.38166 | I34: ='Model inputs'!I64+'Model inputs'!I55 -> 466.91487 | J34: ='Model inputs'!J64+'Model inputs'!J55 -> 503.33127 | ... N34: ='Model inputs'!N64+'Model inputs'!N55 -> 638.44938
A35: Infra and inference (USD) > Household | B35: ='Model inputs'!B29 -> 0 | C35: ='Model inputs'!C65+'Model inputs'!C56 -> 118.01699 | D35: ='Model inputs'!D65+'Model inputs'!D56 -> 141.63405 | E35: ='Model inputs'!E65+'Model inputs'!E56 -> 163.29254 | F35: ='Model inputs'!F65+'Model inputs'!F56 -> 183.17685 | G35: ='Model inputs'!G65+'Model inputs'!G56 -> 201.44248 | H35: ='Model inputs'!H65+'Model inputs'!H56 -> 218.22631 | I35: ='Model inputs'!I65+'Model inputs'!I56 -> 233.65129 | J35: ='Model inputs'!J65+'Model inputs'!J56 -> 247.82891 | ... N35: ='Model inputs'!N65+'Model inputs'!N56 -> 293.974
A36: Revenue (USD) | B36: =SUM('Model inputs'!B37,'Model inputs'!B38) -> 0 | C36: =SUM('Model inputs'!C37,'Model inputs'!C38) -> 623.452 | D36: =SUM('Model inputs'!D37,'Model inputs'!D38) -> 674.01084 | E36: =SUM('Model inputs'!E37,'Model inputs'!E38) -> 721.50952 | F36: =SUM('Model inputs'!F37,'Model inputs'!F38) -> 766.16332 | G36: =SUM('Model inputs'!G37,'Model inputs'!G38) -> 808.17119 | H36: =SUM('Model inputs'!H37,'Model inputs'!H38) -> 847.71699 | I36: =SUM('Model inputs'!I37,'Model inputs'!I38) -> 884.97074 | ... N36: =SUM('Model inputs'!N37,'Model inputs'!N38) -> 1041.9674
A37: Revenue (USD) > Classroom | B37: =0 -> 0 | C37: ='Model inputs'!C76+'Model inputs'!C67 -> 310.3 | D37: ='Model inputs'!D76+'Model inputs'!D67 -> 329.991 | E37: ='Model inputs'!E76+'Model inputs'!E67 -> 349.09127 | F37: ='Model inputs'!F76+'Model inputs'!F67 -> 367.61853 | G37: ='Model inputs'!G76+'Model inputs'!G67 -> 385.58998 | H37: ='Model inputs'!H76+'Model inputs'!H67 -> 403.02228 | I37: ='Model inputs'!I76+'Model inputs'!I67 -> 419.93161 | J37: ='Model inputs'!J76+'Model inputs'!J67 -> 436.33366 | ... N37: ='Model inputs'!N76+'Model inputs'!N67 -> 497.16667
A38: Revenue (USD) > Household | B38: =0 -> 0 | C38: ='Model inputs'!C77+'Model inputs'!C68 -> 313.152 | D38: ='Model inputs'!D77+'Model inputs'!D68 -> 344.01984 | E38: ='Model inputs'!E77+'Model inputs'!E68 -> 372.41825 | F38: ='Model inputs'!F77+'Model inputs'!F68 -> 398.54479 | G38: ='Model inputs'!G77+'Model inputs'!G68 -> 422.58121 | H38: ='Model inputs'!H77+'Model inputs'!H68 -> 444.69471 | I38: ='Model inputs'!I77+'Model inputs'!I68 -> 465.03914 | J38: ='Model inputs'!J77+'Model inputs'!J68 -> 483.756 | ... N38: ='Model inputs'!N77+'Model inputs'!N68 -> 544.80072
A39: Revenue (USD) | B39: =SUM('Model inputs'!B40,'Model inputs'!B41) -> 0 | C39: =SUM('Model inputs'!C40,'Model inputs'!C41) -> 595.18 | D39: =SUM('Model inputs'!D40,'Model inputs'!D41) -> 617.967 | E39: =SUM('Model inputs'!E40,'Model inputs'!E41) -> 638.31731 | F39: =SUM('Model inputs'!F40,'Model inputs'!F41) -> 656.53755 | G39: =SUM('Model inputs'!G40,'Model inputs'!G41) -> 672.89189 | H39: =SUM('Model inputs'!H40,'Model inputs'!H41) -> 687.60817 | I39: =SUM('Model inputs'!I40,'Model inputs'!I41) -> 700.88321 | ... N39: =SUM('Model inputs'!N40,'Model inputs'!N41) -> 750.86514
A40: Revenue (USD) > Classroom | B40: ='Model inputs'!B37 -> 0 | C40: ='Model inputs'!C79+'Model inputs'!C70 -> 301.6 | D40: ='Model inputs'!D79+'Model inputs'!D70 -> 312.504 | E40: ='Model inputs'!E79+'Model inputs'!E70 -> 322.75376 | F40: ='Model inputs'!F79+'Model inputs'!F70 -> 332.38853 | G40: ='Model inputs'!G79+'Model inputs'!G70 -> 341.44522 | H40: ='Model inputs'!H79+'Model inputs'!H70 -> 349.95851 | I40: ='Model inputs'!I79+'Model inputs'!I70 -> 357.961 | J40: ='Model inputs'!J79+'Model inputs'!J70 -> 365.48334 | ... N40: ='Model inputs'!N79+'Model inputs'!N70 -> 391.32207
A41: Revenue (USD) > Household | B41: ='Model inputs'!B38 -> 0 | C41: ='Model inputs'!C80+'Model inputs'!C71 -> 293.58 | D41: ='Model inputs'!D80+'Model inputs'!D71 -> 305.463 | E41: ='Model inputs'!E80+'Model inputs'!E71 -> 315.56355 | F41: ='Model inputs'!F80+'Model inputs'!F71 -> 324.14902 | G41: ='Model inputs'!G80+'Model inputs'!G71 -> 331.44666 | H41: ='Model inputs'!H80+'Model inputs'!H71 -> 337.64967 | I41: ='Model inputs'!I80+'Model inputs'!I71 -> 342.92222 | J41: ='Model inputs'!J80+'Model inputs'!J71 -> 347.40388 | ... N41: ='Model inputs'!N80+'Model inputs'!N71 -> 359.54307
...

Sheet Export notes
A1: Export notes
A2: These cells hold the value cfo.ai calculated instead of a formula. They do not recalculate when you edit an input.
A4: Sheet | B4: Cell | C4: Variable | D4: Period | E4: Scenario | F4: Why
A5: Model inputs | B5: O318 | C5: Share of gated uplift paid (derived) | E5: Main Scenario | F5: It reads Verification policy, which this workbook does not contain.
A6: Model inputs | B6: O321 | C6: Share of gated uplift paid (derived) | E6: Downside | F6: It reads Verification policy, which this workbook does not contain.
A7: Model inputs | B7: O324 | C7: Share of gated uplift paid (derived) | E7: Growth | F7: It reads Verification policy, which this workbook does not contain.
