Workbook

Sheet Unit economics by plan, month 6
A1: Unit economics by plan, month 6 (Main vs Growth vs Downside)
A2: Unit economics · Main Scenario
A4: Variable / dimension | B4: 2027-03 | C4: 2027-03 > Growth | D4: 2027-03 > Downside
A5: Ending customers | B5: =SUM('Unit economics by plan, month 6'!B6,'Unit economics by plan, month 6'!B7) -> 77.51602 | C5: =SUM('Unit economics by plan, month 6'!C6,'Unit economics by plan, month 6'!C7) -> 128.01572 | D5: =SUM('Unit economics by plan, month 6'!D6,'Unit economics by plan, month 6'!D7) -> 60.372208
A6: Classroom | B6: ='Unit economics by plan (monthly'!F12+'Unit economics by plan (monthly'!G6-'Unit economics by plan (monthly'!G9 -> 13.89732 | C6: ='Model inputs'!G32+'Model inputs'!H83-'Model inputs'!H16 -> 25.03252 | D6: ='Model inputs'!G29+'Model inputs'!H80-'Model inputs'!H13 -> 12.067535
A7: Household | B7: ='Unit economics by plan (monthly'!F13+'Unit economics by plan (monthly'!G7-'Unit economics by plan (monthly'!G10 -> 63.6187 | C7: ='Model inputs'!G33+'Model inputs'!H84-'Model inputs'!H17 -> 102.9832 | D7: ='Model inputs'!G30+'Model inputs'!H81-'Model inputs'!H14 -> 48.304673
A8: Revenue (USD) | B8: =SUM('Unit economics by plan, month 6'!B9,'Unit economics by plan, month 6'!B10) -> 847.71699 | C8: =SUM('Unit economics by plan, month 6'!C9,'Unit economics by plan, month 6'!C10) -> 1445.7956 | D8: =SUM('Unit economics by plan, month 6'!D9,'Unit economics by plan, month 6'!D10) -> 687.60817
A9: Classroom | B9: ='Unit economics by plan (monthly'!G18+'Unit economics by plan (monthly'!G21 -> 403.02228 | C9: ='Model inputs'!H117+'Model inputs'!H95 -> 725.94307 | D9: ='Model inputs'!H114+'Model inputs'!H92 -> 349.95851
A10: Household | B10: ='Unit economics by plan (monthly'!G19+'Unit economics by plan (monthly'!G22 -> 444.69471 | C10: ='Model inputs'!H118+'Model inputs'!H96 -> 719.85257 | D10: ='Model inputs'!H115+'Model inputs'!H93 -> 337.64967
A11: Infra and inference (USD) | B11: =SUM('Unit economics by plan, month 6'!B12,'Unit economics by plan, month 6'!B13) -> 278.082 | C11: =SUM('Unit economics by plan, month 6'!C12,'Unit economics by plan, month 6'!C13) -> 647.60797 | D11: =SUM('Unit economics by plan, month 6'!D12,'Unit economics by plan, month 6'!D13) -> 406.4699
A12: Classroom | B12: ='Unit economics by plan (monthly'!G27+'Gross profit and margin by plan'!G8 -> 175.23462 | C12: ='Model inputs'!H54+'Model inputs'!H41 -> 429.38166 | D12: ='Model inputs'!H51+'Model inputs'!H38 -> 270.4139
A13: Household | B13: ='Unit economics by plan (monthly'!G28+'Gross profit and margin by plan'!G9 -> 102.84738 | C13: ='Model inputs'!H55+'Model inputs'!H42 -> 218.22631 | D13: ='Model inputs'!H52+'Model inputs'!H39 -> 136.056
A14: Gross profit (USD) | B14: =SUM('Unit economics by plan, month 6'!B15,'Unit economics by plan, month 6'!B16) -> 569.63499 | C14: =SUM('Unit economics by plan, month 6'!C15,'Unit economics by plan, month 6'!C16) -> 798.18766 | D14: =SUM('Unit economics by plan, month 6'!D15,'Unit economics by plan, month 6'!D16) -> 281.13828
A15: Classroom | B15: ='Unit economics by plan, month 6'!B9-'Unit economics by plan, month 6'!B12 -> 227.78766 | C15: ='Unit economics by plan, month 6'!C9-'Unit economics by plan, month 6'!C12 -> 296.56141 | D15: ='Unit economics by plan, month 6'!D9-'Unit economics by plan, month 6'!D12 -> 79.544609
A16: Household | B16: ='Unit economics by plan, month 6'!B10-'Unit economics by plan, month 6'!B13 -> 341.84733 | C16: ='Unit economics by plan, month 6'!C10-'Unit economics by plan, month 6'!C13 -> 501.62625 | D16: ='Unit economics by plan, month 6'!D10-'Unit economics by plan, month 6'!D13 -> 201.59367
A17: Gross margin | B17: =IFERROR('Unit economics by plan, month 6'!B14/'Unit economics by plan, month 6'!B8,0) -> 0.67196363 | C17: =IFERROR('Unit economics by plan, month 6'!C14/'Unit economics by plan, month 6'!C8,0) -> 0.55207503 | D17: =IFERROR('Unit economics by plan, month 6'!D14/'Unit economics by plan, month 6'!D8,0) -> 0.40886407
A18: Classroom | B18: =IFERROR('Unit economics by plan, month 6'!B15/'Unit economics by plan, month 6'!B9,0) -> 0.56519868 | C18: =IFERROR('Unit economics by plan, month 6'!C15/'Unit economics by plan, month 6'!C9,0) -> 0.40851883 | D18: =IFERROR('Unit economics by plan, month 6'!D15/'Unit economics by plan, month 6'!D9,0) -> 0.22729726
A19: Household | B19: =IFERROR('Unit economics by plan, month 6'!B16/'Unit economics by plan, month 6'!B10,0) -> 0.76872362 | C19: =IFERROR('Unit economics by plan, month 6'!C16/'Unit economics by plan, month 6'!C10,0) -> 0.69684582 | D19: =IFERROR('Unit economics by plan, month 6'!D16/'Unit economics by plan, month 6'!D10,0) -> 0.59704981
A20: Clears gross margin bar (1 = yes) | B20: =IF(IF(IF(ISERROR('Unit economics by plan, month 6'!B17>='Model inputs'!O34),'Unit economics by plan, month 6'!B17>='Model inputs'!O34,IF(OR('Unit economics by plan, month 6'!B17="",'Model inputs'!O34=""),"",'Unit economics by plan, month 6'!B17>='Model inputs'!O34))="",FALSE,IF(ISERROR('Unit economics by plan, month 6'!B17>='Model inputs'!O34),'Unit economics by plan, month 6'!B17>='Model inputs'!O34,IF(OR('Unit economics by plan, month 6'!B17="",'Model inputs'!O34=""),"",'Unit economics by plan, month 6'!B17>='Model inputs'!O34))),1,0) -> 1 | C20: =IF(IF(IF(ISERROR('Unit economics by plan, month 6'!C17>='Model inputs'!O36),'Unit economics by plan, month 6'!C17>='Model inputs'!O36,IF(OR('Unit economics by plan, month 6'!C17="",'Model inputs'!O36=""),"",'Unit economics by plan, month 6'!C17>='Model inputs'!O36))="",FALSE,IF(ISERROR('Unit economics by plan, month 6'!C17>='Model inputs'!O36),'Unit economics by plan, month 6'!C17>='Model inputs'!O36,IF(OR('Unit economics by plan, month 6'!C17="",'Model inputs'!O36=""),"",'Unit economics by plan, month 6'!C17>='Model inputs'!O36))),1,0) -> 0 | D20: =IF(IF(IF(ISERROR('Unit economics by plan, month 6'!D17>='Model inputs'!O35),'Unit economics by plan, month 6'!D17>='Model inputs'!O35,IF(OR('Unit economics by plan, month 6'!D17="",'Model inputs'!O35=""),"",'Unit economics by plan, month 6'!D17>='Model inputs'!O35))="",FALSE,IF(ISERROR('Unit economics by plan, month 6'!D17>='Model inputs'!O35),'Unit economics by plan, month 6'!D17>='Model inputs'!O35,IF(OR('Unit economics by plan, month 6'!D17="",'Model inputs'!O35=""),"",'Unit economics by plan, month 6'!D17>='Model inputs'!O35))),1,0) -> 0
A21: Runway in months (0 = not burning cash) | B21: =IF(IF(IF(ISERROR('Model inputs'!H70<0),'Model inputs'!H70<0,IF('Model inputs'!H70="","",'Model inputs'!H70<0))="",FALSE,IF(ISERROR('Model inputs'!H70<0),'Model inputs'!H70<0,IF('Model inputs'!H70="","",'Model inputs'!H70<0))),'Model inputs'!H19/-'Model inputs'!H70,0) -> 0 | C21: =IF(IF(IF(ISERROR('Model inputs'!H72<0),'Model inputs'!H72<0,IF('Model inputs'!H72="","",'Model inputs'!H72<0))="",FALSE,IF(ISERROR('Model inputs'!H72<0),'Model inputs'!H72<0,IF('Model inputs'!H72="","",'Model inputs'!H72<0))),'Model inputs'!H21/-'Model inputs'!H72,0) -> 0 | D21: =IF(IF(IF(ISERROR('Model inputs'!H71<0),'Model inputs'!H71<0,IF('Model inputs'!H71="","",'Model inputs'!H71<0))="",FALSE,IF(ISERROR('Model inputs'!H71<0),'Model inputs'!H71<0,IF('Model inputs'!H71="","",'Model inputs'!H71<0))),'Model inputs'!H20/-'Model inputs'!H71,0) -> 0

Sheet Unit economics by plan (monthly
A1: Unit economics by plan (monthly)
A2: Unit economics · Main Scenario
A4: Variable / dimension | B4: 2026-10 | C4: 2026-11 | D4: 2026-12 | E4: 2027-01 | F4: 2027-02 | G4: 2027-03 | H4: 2027-04 | I4: 2027-05 | J4: 2027-06 | K4: 2027-07 | L4: 2027-08 | M4: 2027-09
A5: New customers | B5: =SUM('Unit economics by plan (monthly'!B6,'Unit economics by plan (monthly'!B7) -> 9 | C5: =SUM('Unit economics by plan (monthly'!C6,'Unit economics by plan (monthly'!C7) -> 9 | D5: =SUM('Unit economics by plan (monthly'!D6,'Unit economics by plan (monthly'!D7) -> 9 | E5: =SUM('Unit economics by plan (monthly'!E6,'Unit economics by plan (monthly'!E7) -> 9 | F5: =SUM('Unit economics by plan (monthly'!F6,'Unit economics by plan (monthly'!F7) -> 9 | G5: =SUM('Unit economics by plan (monthly'!G6,'Unit economics by plan (monthly'!G7) -> 9 | H5: =SUM('Unit economics by plan (monthly'!H6,'Unit economics by plan (monthly'!H7) -> 9 | I5: =SUM('Unit economics by plan (monthly'!I6,'Unit economics by plan (monthly'!I7) -> 9 | ... M5: =SUM('Unit economics by plan (monthly'!M6,'Unit economics by plan (monthly'!M7) -> 9
A6: Classroom | B6: =IF('Model inputs'!O86="","",'Model inputs'!O86) -> 1 | C6: =IF('Model inputs'!O86="","",'Model inputs'!O86) -> 1 | D6: =IF('Model inputs'!O86="","",'Model inputs'!O86) -> 1 | E6: =IF('Model inputs'!O86="","",'Model inputs'!O86) -> 1 | F6: =IF('Model inputs'!O86="","",'Model inputs'!O86) -> 1 | G6: =IF('Model inputs'!O86="","",'Model inputs'!O86) -> 1 | H6: =IF('Model inputs'!O86="","",'Model inputs'!O86) -> 1 | I6: =IF('Model inputs'!O86="","",'Model inputs'!O86) -> 1 | J6: =IF('Model inputs'!O86="","",'Model inputs'!O86) -> 1 | K6: =IF('Model inputs'!O86="","",'Model inputs'!O86) -> 1 | L6: =IF('Model inputs'!O86="","",'Model inputs'!O86) -> 1 | M6: =IF('Model inputs'!O86="","",'Model inputs'!O86) -> 1
A7: Household | B7: =IF('Model inputs'!O87="","",'Model inputs'!O87) -> 8 | C7: =IF('Model inputs'!O87="","",'Model inputs'!O87) -> 8 | D7: =IF('Model inputs'!O87="","",'Model inputs'!O87) -> 8 | E7: =IF('Model inputs'!O87="","",'Model inputs'!O87) -> 8 | F7: =IF('Model inputs'!O87="","",'Model inputs'!O87) -> 8 | G7: =IF('Model inputs'!O87="","",'Model inputs'!O87) -> 8 | H7: =IF('Model inputs'!O87="","",'Model inputs'!O87) -> 8 | I7: =IF('Model inputs'!O87="","",'Model inputs'!O87) -> 8 | J7: =IF('Model inputs'!O87="","",'Model inputs'!O87) -> 8 | K7: =IF('Model inputs'!O87="","",'Model inputs'!O87) -> 8 | L7: =IF('Model inputs'!O87="","",'Model inputs'!O87) -> 8 | M7: =IF('Model inputs'!O87="","",'Model inputs'!O87) -> 8
A8: Churned customers | B8: =SUM('Unit economics by plan (monthly'!B9,'Unit economics by plan (monthly'!B10) -> 3.5 | C8: =SUM('Unit economics by plan (monthly'!C9,'Unit economics by plan (monthly'!C10) -> 3.905 | D8: =SUM('Unit economics by plan (monthly'!D9,'Unit economics by plan (monthly'!D10) -> 4.27865 | E8: =SUM('Unit economics by plan (monthly'!E9,'Unit economics by plan (monthly'!E10) -> 4.6234265 | F8: =SUM('Unit economics by plan (monthly'!F9,'Unit economics by plan (monthly'!F10) -> 4.9416088 | G8: =SUM('Unit economics by plan (monthly'!G9,'Unit economics by plan (monthly'!G10) -> 5.2352949 | H8: =SUM('Unit economics by plan (monthly'!H9,'Unit economics by plan (monthly'!H10) -> 5.5064156 | I8: =SUM('Unit economics by plan (monthly'!I9,'Unit economics by plan (monthly'!I10) -> 5.7567483 | ... M8: =SUM('Unit economics by plan (monthly'!M9,'Unit economics by plan (monthly'!M10) -> 6.5810296
A9: Classroom | B9: ='Model inputs'!B23*'Model inputs'!O63 -> 0.3 | C9: ='Unit economics by plan (monthly'!B12*'Model inputs'!O63 -> 0.321 | D9: ='Unit economics by plan (monthly'!C12*'Model inputs'!O63 -> 0.34137 | E9: ='Unit economics by plan (monthly'!D12*'Model inputs'!O63 -> 0.3611289 | F9: ='Unit economics by plan (monthly'!E12*'Model inputs'!O63 -> 0.38029503 | G9: ='Unit economics by plan (monthly'!F12*'Model inputs'!O63 -> 0.39888618 | H9: ='Unit economics by plan (monthly'!G12*'Model inputs'!O63 -> 0.4169196 | I9: ='Unit economics by plan (monthly'!H12*'Model inputs'!O63 -> 0.43441201 | J9: ='Unit economics by plan (monthly'!I12*'Model inputs'!O63 -> 0.45137965 | K9: ='Unit economics by plan (monthly'!J12*'Model inputs'!O63 -> 0.46783826 | L9: ='Unit economics by plan (monthly'!K12*'Model inputs'!O63 -> 0.48380311 | M9: ='Unit economics by plan (monthly'!L12*'Model inputs'!O63 -> 0.49928902
A10: Household | B10: ='Model inputs'!B24*'Model inputs'!O64 -> 3.2 | C10: ='Unit economics by plan (monthly'!B13*'Model inputs'!O64 -> 3.584 | D10: ='Unit economics by plan (monthly'!C13*'Model inputs'!O64 -> 3.93728 | E10: ='Unit economics by plan (monthly'!D13*'Model inputs'!O64 -> 4.2622976 | F10: ='Unit economics by plan (monthly'!E13*'Model inputs'!O64 -> 4.5613138 | G10: ='Unit economics by plan (monthly'!F13*'Model inputs'!O64 -> 4.8364087 | H10: ='Unit economics by plan (monthly'!G13*'Model inputs'!O64 -> 5.089496 | I10: ='Unit economics by plan (monthly'!H13*'Model inputs'!O64 -> 5.3223363 | J10: ='Unit economics by plan (monthly'!I13*'Model inputs'!O64 -> 5.5365494 | K10: ='Unit economics by plan (monthly'!J13*'Model inputs'!O64 -> 5.7336255 | L10: ='Unit economics by plan (monthly'!K13*'Model inputs'!O64 -> 5.9149354 | M10: ='Unit economics by plan (monthly'!L13*'Model inputs'!O64 -> 6.0817406
A11: Ending customers | B11: =SUM('Unit economics by plan (monthly'!B12,'Unit economics by plan (monthly'!B13) -> 55.5 | C11: =SUM('Unit economics by plan (monthly'!C12,'Unit economics by plan (monthly'!C13) -> 60.595 | D11: =SUM('Unit economics by plan (monthly'!D12,'Unit economics by plan (monthly'!D13) -> 65.31635 | E11: =SUM('Unit economics by plan (monthly'!E12,'Unit economics by plan (monthly'!E13) -> 69.692923 | F11: =SUM('Unit economics by plan (monthly'!F12,'Unit economics by plan (monthly'!F13) -> 73.751315 | G11: =SUM('Unit economics by plan (monthly'!G12,'Unit economics by plan (monthly'!G13) -> 77.51602 | H11: =SUM('Unit economics by plan (monthly'!H12,'Unit economics by plan (monthly'!H13) -> 81.009604 | I11: =SUM('Unit economics by plan (monthly'!I12,'Unit economics by plan (monthly'!I13) -> 84.252856 | ... M11: =SUM('Unit economics by plan (monthly'!M12,'Unit economics by plan (monthly'!M13) -> 95.083695
A12: Classroom | B12: ='Model inputs'!B23+'Unit economics by plan (monthly'!B6-'Unit economics by plan (monthly'!B9 -> 10.7 | C12: ='Unit economics by plan (monthly'!B12+'Unit economics by plan (monthly'!C6-'Unit economics by plan (monthly'!C9 -> 11.379 | D12: ='Unit economics by plan (monthly'!C12+'Unit economics by plan (monthly'!D6-'Unit economics by plan (monthly'!D9 -> 12.03763 | E12: ='Unit economics by plan (monthly'!D12+'Unit economics by plan (monthly'!E6-'Unit economics by plan (monthly'!E9 -> 12.676501 | F12: ='Unit economics by plan (monthly'!E12+'Unit economics by plan (monthly'!F6-'Unit economics by plan (monthly'!F9 -> 13.296206 | G12: ='Unit economics by plan (monthly'!F12+'Unit economics by plan (monthly'!G6-'Unit economics by plan (monthly'!G9 -> 13.89732 | H12: ='Unit economics by plan (monthly'!G12+'Unit economics by plan (monthly'!H6-'Unit economics by plan (monthly'!H9 -> 14.4804 | I12: ='Unit economics by plan (monthly'!H12+'Unit economics by plan (monthly'!I6-'Unit economics by plan (monthly'!I9 -> 15.045988 | J12: ='Unit economics by plan (monthly'!I12+'Unit economics by plan (monthly'!J6-'Unit economics by plan (monthly'!J9 -> 15.594609 | ... M12: ='Unit economics by plan (monthly'!L12+'Unit economics by plan (monthly'!M6-'Unit economics by plan (monthly'!M9 -> 17.143678
A13: Household | B13: ='Model inputs'!B24+'Unit economics by plan (monthly'!B7-'Unit economics by plan (monthly'!B10 -> 44.8 | C13: ='Unit economics by plan (monthly'!B13+'Unit economics by plan (monthly'!C7-'Unit economics by plan (monthly'!C10 -> 49.216 | D13: ='Unit economics by plan (monthly'!C13+'Unit economics by plan (monthly'!D7-'Unit economics by plan (monthly'!D10 -> 53.27872 | E13: ='Unit economics by plan (monthly'!D13+'Unit economics by plan (monthly'!E7-'Unit economics by plan (monthly'!E10 -> 57.016422 | F13: ='Unit economics by plan (monthly'!E13+'Unit economics by plan (monthly'!F7-'Unit economics by plan (monthly'!F10 -> 60.455109 | G13: ='Unit economics by plan (monthly'!F13+'Unit economics by plan (monthly'!G7-'Unit economics by plan (monthly'!G10 -> 63.6187 | H13: ='Unit economics by plan (monthly'!G13+'Unit economics by plan (monthly'!H7-'Unit economics by plan (monthly'!H10 -> 66.529204 | I13: ='Unit economics by plan (monthly'!H13+'Unit economics by plan (monthly'!I7-'Unit economics by plan (monthly'!I10 -> 69.206868 | J13: ='Unit economics by plan (monthly'!I13+'Unit economics by plan (monthly'!J7-'Unit economics by plan (monthly'!J10 -> 71.670318 | ... M13: ='Unit economics by plan (monthly'!L13+'Unit economics by plan (monthly'!M7-'Unit economics by plan (monthly'!M10 -> 77.940017
A14: Stories delivered | B14: =SUM('Unit economics by plan (monthly'!B15,'Unit economics by plan (monthly'!B16) -> 964.56 | C14: =SUM('Unit economics by plan (monthly'!C15,'Unit economics by plan (monthly'!C16) -> 1037.0952 | D14: =SUM('Unit economics by plan (monthly'!D15,'Unit economics by plan (monthly'!D16) -> 1105.8646 | E14: =SUM('Unit economics by plan (monthly'!E15,'Unit economics by plan (monthly'!E16) -> 1171.1083 | F14: =SUM('Unit economics by plan (monthly'!F15,'Unit economics by plan (monthly'!F16) -> 1233.0491 | G14: =SUM('Unit economics by plan (monthly'!G15,'Unit economics by plan (monthly'!G16) -> 1291.8938 | H14: =SUM('Unit economics by plan (monthly'!H15,'Unit economics by plan (monthly'!H16) -> 1347.8343 | I14: =SUM('Unit economics by plan (monthly'!I15,'Unit economics by plan (monthly'!I16) -> 1401.0487 | ... M14: =SUM('Unit economics by plan (monthly'!M15,'Unit economics by plan (monthly'!M16) -> 1589.7888
A15: Classroom | B15: ='Unit economics by plan (monthly'!B12*'Model inputs'!O111 -> 642 | C15: ='Unit economics by plan (monthly'!C12*'Model inputs'!O111 -> 682.74 | D15: ='Unit economics by plan (monthly'!D12*'Model inputs'!O111 -> 722.2578 | E15: ='Unit economics by plan (monthly'!E12*'Model inputs'!O111 -> 760.59007 | F15: ='Unit economics by plan (monthly'!F12*'Model inputs'!O111 -> 797.77236 | G15: ='Unit economics by plan (monthly'!G12*'Model inputs'!O111 -> 833.83919 | H15: ='Unit economics by plan (monthly'!H12*'Model inputs'!O111 -> 868.82402 | I15: ='Unit economics by plan (monthly'!I12*'Model inputs'!O111 -> 902.7593 | J15: ='Unit economics by plan (monthly'!J12*'Model inputs'!O111 -> 935.67652 | K15: ='Unit economics by plan (monthly'!K12*'Model inputs'!O111 -> 967.60622 | L15: ='Unit economics by plan (monthly'!L12*'Model inputs'!O111 -> 998.57804 | M15: ='Unit economics by plan (monthly'!M12*'Model inputs'!O111 -> 1028.6207
A16: Household | B16: ='Unit economics by plan (monthly'!B13*'Model inputs'!O112 -> 322.56 | C16: ='Unit economics by plan (monthly'!C13*'Model inputs'!O112 -> 354.3552 | D16: ='Unit economics by plan (monthly'!D13*'Model inputs'!O112 -> 383.60678 | E16: ='Unit economics by plan (monthly'!E13*'Model inputs'!O112 -> 410.51824 | F16: ='Unit economics by plan (monthly'!F13*'Model inputs'!O112 -> 435.27678 | G16: ='Unit economics by plan (monthly'!G13*'Model inputs'!O112 -> 458.05464 | H16: ='Unit economics by plan (monthly'!H13*'Model inputs'!O112 -> 479.01027 | I16: ='Unit economics by plan (monthly'!I13*'Model inputs'!O112 -> 498.28945 | J16: ='Unit economics by plan (monthly'!J13*'Model inputs'!O112 -> 516.02629 | K16: ='Unit economics by plan (monthly'!K13*'Model inputs'!O112 -> 532.34419 | L16: ='Unit economics by plan (monthly'!L13*'Model inputs'!O112 -> 547.35665 | M16: ='Unit economics by plan (monthly'!M13*'Model inputs'!O112 -> 561.16812
A17: Subscription revenue (USD) | B17: =SUM('Unit economics by plan (monthly'!B18,'Unit economics by plan (monthly'!B19) -> 623.452 | C17: =SUM('Unit economics by plan (monthly'!C18,'Unit economics by plan (monthly'!C19) -> 674.01084 | D17: =SUM('Unit economics by plan (monthly'!D18,'Unit economics by plan (monthly'!D19) -> 721.50952 | E17: =SUM('Unit economics by plan (monthly'!E18,'Unit economics by plan (monthly'!E19) -> 766.16332 | F17: =SUM('Unit economics by plan (monthly'!F18,'Unit economics by plan (monthly'!F19) -> 808.17119 | G17: =SUM('Unit economics by plan (monthly'!G18,'Unit economics by plan (monthly'!G19) -> 847.71699 | H17: =SUM('Unit economics by plan (monthly'!H18,'Unit economics by plan (monthly'!H19) -> 884.97074 | I17: =SUM('Unit economics by plan (monthly'!I18,'Unit economics by plan (monthly'!I19) -> 920.08966 | ... M17: =SUM('Unit economics by plan (monthly'!M18,'Unit economics by plan (monthly'!M19) -> 1041.9674
A18: Classroom | B18: ='Unit economics by plan (monthly'!B12*'Model inputs'!O104 -> 310.3 | C18: ='Unit economics by plan (monthly'!C12*'Model inputs'!O104 -> 329.991 | D18: ='Unit economics by plan (monthly'!D12*'Model inputs'!O104 -> 349.09127 | E18: ='Unit economics by plan (monthly'!E12*'Model inputs'!O104 -> 367.61853 | F18: ='Unit economics by plan (monthly'!F12*'Model inputs'!O104 -> 385.58998 | G18: ='Unit economics by plan (monthly'!G12*'Model inputs'!O104 -> 403.02228 | H18: ='Unit economics by plan (monthly'!H12*'Model inputs'!O104 -> 419.93161 | I18: ='Unit economics by plan (monthly'!I12*'Model inputs'!O104 -> 436.33366 | J18: ='Unit economics by plan (monthly'!J12*'Model inputs'!O104 -> 452.24365 | K18: ='Unit economics by plan (monthly'!K12*'Model inputs'!O104 -> 467.67634 | L18: ='Unit economics by plan (monthly'!L12*'Model inputs'!O104 -> 482.64605 | M18: ='Unit economics by plan (monthly'!M12*'Model inputs'!O104 -> 497.16667
A19: Household | B19: ='Unit economics by plan (monthly'!B13*'Model inputs'!O105 -> 313.152 | C19: ='Unit economics by plan (monthly'!C13*'Model inputs'!O105 -> 344.01984 | D19: ='Unit economics by plan (monthly'!D13*'Model inputs'!O105 -> 372.41825 | E19: ='Unit economics by plan (monthly'!E13*'Model inputs'!O105 -> 398.54479 | F19: ='Unit economics by plan (monthly'!F13*'Model inputs'!O105 -> 422.58121 | G19: ='Unit economics by plan (monthly'!G13*'Model inputs'!O105 -> 444.69471 | H19: ='Unit economics by plan (monthly'!H13*'Model inputs'!O105 -> 465.03914 | I19: ='Unit economics by plan (monthly'!I13*'Model inputs'!O105 -> 483.756 | J19: ='Unit economics by plan (monthly'!J13*'Model inputs'!O105 -> 500.97552 | K19: ='Unit economics by plan (monthly'!K13*'Model inputs'!O105 -> 516.81748 | L19: ='Unit economics by plan (monthly'!L13*'Model inputs'!O105 -> 531.39208 | M19: ='Unit economics by plan (monthly'!M13*'Model inputs'!O105 -> 544.80072
A20: Overage revenue (USD) | B20: =SUM('Unit economics by plan (monthly'!B21,'Unit economics by plan (monthly'!B22) -> 0 | C20: =SUM('Unit economics by plan (monthly'!C21,'Unit economics by plan (monthly'!C22) -> 0 | D20: =SUM('Unit economics by plan (monthly'!D21,'Unit economics by plan (monthly'!D22) -> 0 | E20: =SUM('Unit economics by plan (monthly'!E21,'Unit economics by plan (monthly'!E22) -> 0 | F20: =SUM('Unit economics by plan (monthly'!F21,'Unit economics by plan (monthly'!F22) -> 0 | G20: =SUM('Unit economics by plan (monthly'!G21,'Unit economics by plan (monthly'!G22) -> 0 | H20: =SUM('Unit economics by plan (monthly'!H21,'Unit economics by plan (monthly'!H22) -> 0 | I20: =SUM('Unit economics by plan (monthly'!I21,'Unit economics by plan (monthly'!I22) -> 0 | ... M20: =SUM('Unit economics by plan (monthly'!M21,'Unit economics by plan (monthly'!M22) -> 0
A21: Classroom | B21: ='Unit economics by plan (monthly'!B12*IF(IF(IF(IF(ISERROR('Model inputs'!O111>'Model inputs'!O108),'Model inputs'!O111>'Model inputs'!O108,IF(OR('Model inputs'!O111="",'Model inputs'!O108=""),"",'Model inputs'!O111>'Model inputs'!O108))="",FALSE,IF(ISERROR('Model inputs'!O111>'Model inputs'!O108),'Model inputs'!O111>'Model inputs'!O108,IF(OR('Model inputs'!O111="",'Model inputs'!O108=""),"",'Model inputs'!O111>'Model inputs'!O108))),('Model inputs'!O111-'Model inputs'!O108)*'Model inputs'!O89,0)="",0,IF(IF(IF(ISERROR('Model inputs'!O111>'Model inputs'!O108),'Model inputs'!O111>'Model inputs'!O108,IF(OR('Model inputs'!O111="",'Model inputs'!O108=""),"",'Model inputs'!O111>'Model inputs'!O108))="",FALSE,IF(ISERROR('Model inputs'!O111>'Model inputs'!O108),'Model inputs'!O111>'Model inputs'!O108,IF(OR('Model inputs'!O111="",'Model inputs'!O108=""),"",'Model inputs'!O111>'Model inputs'!O108))),('Model inputs'!O111-'Model inputs'!O108)*'Model inputs'!O89,0)) -> 0 | C21: ='Unit economics by plan (monthly'!C12*IF(IF(IF(IF(ISERROR('Model inputs'!O111>'Model inputs'!O108),'Model inputs'!O111>'Model inputs'!O108,IF(OR('Model inputs'!O111="",'Model inputs'!O108=""),"",'Model inputs'!O111>'Model inputs'!O108))="",FALSE,IF(ISERROR('Model inputs'!O111>'Model inputs'!O108),'Model inputs'!O111>'Model inputs'!O108,IF(OR('Model inputs'!O111="",'Model inputs'!O108=""),"",'Model inputs'!O111>'Model inputs'!O108))),('Model inputs'!O111-'Model inputs'!O108)*'Model inputs'!O89,0)="",0,IF(IF(IF(ISERROR('Model inputs'!O111>'Model inputs'!O108),'Model inputs'!O111>'Model inputs'!O108,IF(OR('Model inputs'!O111="",'Model inputs'!O108=""),"",'Model inputs'!O111>'Model inputs'!O108))="",FALSE,IF(ISERROR('Model inputs'!O111>'Model inputs'!O108),'Model inputs'!O111>'Model inputs'!O108,IF(OR('Model inputs'!O111="",'Model inputs'!O108=""),"",'Model inputs'!O111>'Model inputs'!O108))),('Model inputs'!O111-'Model inputs'!O108)*'Model inputs'!O89,0)) -> 0 | D21: ='Unit economics by plan (monthly'!D12*IF(IF(IF(IF(ISERROR('Model inputs'!O111>'Model inputs'!O108),'Model inputs'!O111>'Model inputs'!O108,IF(OR('Model inputs'!O111="",'Model inputs'!O108=""),"",'Model inputs'!O111>'Model inputs'!O108))="",FALSE,IF(ISERROR('Model inputs'!O111>'Model inputs'!O108),'Model inputs'!O111>'Model inputs'!O108,IF(OR('Model inputs'!O111="",'Model inputs'!O108=""),"",'Model inputs'!O111>'Model inputs'!O108))),('Model inputs'!O111-'Model inputs'!O108)*'Model inputs'!O89,0)="",0,IF(IF(IF(ISERROR('Model inputs'!O111>'Model inputs'!O108),'Model inputs'!O111>'Model inputs'!O108,IF(OR('Model inputs'!O111="",'Model inputs'!O108=""),"",'Model inputs'!O111>'Model inputs'!O108))="",FALSE,IF(ISERROR('Model inputs'!O111>'Model inputs'!O108),'Model inputs'!O111>'Model inputs'!O108,IF(OR('Model inputs'!O111="",'Model inputs'!O108=""),"",'Model inputs'!O111>'Model inputs'!O108))),('Model inputs'!O111-'Model inputs'!O108)*'Model inputs'!O89,0)) -> 0 | E21: ='Unit economics by plan (monthly'!E12*IF(IF(IF(IF(ISERROR('Model inputs'!O111>'Model inputs'!O108),'Model inputs'!O111>'Model inputs'!O108,IF(OR('Model inputs'!O111="",'Model inputs'!O108=""),"",'Model inputs'!O111>'Model inputs'!O108))="",FALSE,IF(ISERROR('Model inputs'!O111>'Model inputs'!O108),'Model inputs'!O111>'Model inputs'!O108,IF(OR('Model inputs'!O111="",'Model inputs'!O108=""),"",'Model inputs'!O111>'Model inputs'!O108))),('Model inputs'!O111-'Model inputs'!O108)*'Model inputs'!O89,0)="",0,IF(IF(IF(ISERROR('Model inputs'!O111>'Model inputs'!O108),'Model inputs'!O111>'Model inputs'!O108,IF(OR('Model inputs'!O111="",'Model inputs'!O108=""),"",'Model inputs'!O111>'Model inputs'!O108))="",FALSE,IF(ISERROR('Model inputs'!O111>'Model inputs'!O108),'Model inputs'!O111>'Model inputs'!O108,IF(OR('Model inputs'!O111="",'Model inputs'!O108=""),"",'Model inputs'!O111>'Model inputs'!O108))),('Model inputs'!O111-'Model inputs'!O108)*'Model inputs'!O89,0)) -> 0 | F21: ='Unit economics by plan (monthly'!F12*IF(IF(IF(IF(ISERROR('Model inputs'!O111>'Model inputs'!O108),'Model inputs'!O111>'Model inputs'!O108,IF(OR('Model inputs'!O111="",'Model inputs'!O108=""),"",'Model inputs'!O111>'Model inputs'!O108))="",FALSE,IF(ISERROR('Model inputs'!O111>'Model inputs'!O108),'Model inputs'!O111>'Model inputs'!O108,IF(OR('Model inputs'!O111="",'Model inputs'!O108=""),"",'Model inputs'!O111>'Model inputs'!O108))),('Model inputs'!O111-'Model inputs'!O108)*'Model inputs'!O89,0)="",0,IF(IF(IF(ISERROR('Model inputs'!O111>'Model inputs'!O108),'Model inputs'!O111>'Model inputs'!O108,IF(OR('Model inputs'!O111="",'Model inputs'!O108=""),"",'Model inputs'!O111>'Model inputs'!O108))="",FALSE,IF(ISERROR('Model inputs'!O111>'Model inputs'!O108),'Model inputs'!O111>'Model inputs'!O108,IF(OR('Model inputs'!O111="",'Model inputs'!O108=""),"",'Model inputs'!O111>'Model inputs'!O108))),('Model inputs'!O111-'Model inputs'!O108)*'Model inputs'!O89,0)) -> 0 | G21: ='Unit economics by plan (monthly'!G12*IF(IF(IF(IF(ISERROR('Model inputs'!O111>'Model inputs'!O108),'Model inputs'!O111>'Model inputs'!O108,IF(OR('Model inputs'!O111="",'Model inputs'!O108=""),"",'Model inputs'!O111>'Model inputs'!O108))="",FALSE,IF(ISERROR('Model inputs'!O111>'Model inputs'!O108),'Model inputs'!O111>'Model inputs'!O108,IF(OR('Model inputs'!O111="",'Model inputs'!O108=""),"",'Model inputs'!O111>'Model inputs'!O108))),('Model inputs'!O111-'Model inputs'!O108)*'Model inputs'!O89,0)="",0,IF(IF(IF(ISERROR('Model inputs'!O111>'Model inputs'!O108),'Model inputs'!O111>'Model inputs'!O108,IF(OR('Model inputs'!O111="",'Model inputs'!O108=""),"",'Model inputs'!O111>'Model inputs'!O108))="",FALSE,IF(ISERROR('Model inputs'!O111>'Model inputs'!O108),'Model inputs'!O111>'Model inputs'!O108,IF(OR('Model inputs'!O111="",'Model inputs'!O108=""),"",'Model inputs'!O111>'Model inputs'!O108))),('Model inputs'!O111-'Model inputs'!O108)*'Model inputs'!O89,0)) -> 0 | H21: ='Unit economics by plan (monthly'!H12*IF(IF(IF(IF(ISERROR('Model inputs'!O111>'Model inputs'!O108),'Model inputs'!O111>'Model inputs'!O108,IF(OR('Model inputs'!O111="",'Model inputs'!O108=""),"",'Model inputs'!O111>'Model inputs'!O108))="",FALSE,IF(ISERROR('Model inputs'!O111>'Model inputs'!O108),'Model inputs'!O111>'Model inputs'!O108,IF(OR('Model inputs'!O111="",'Model inputs'!O108=""),"",'Model inputs'!O111>'Model inputs'!O108))),('Model inputs'!O111-'Model inputs'!O108)*'Model inputs'!O89,0)="",0,IF(IF(IF(ISERROR('Model inputs'!O111>'Model inputs'!O108),'Model inputs'!O111>'Model inputs'!O108,IF(OR('Model inputs'!O111="",'Model inputs'!O108=""),"",'Model inputs'!O111>'Model inputs'!O108))="",FALSE,IF(ISERROR('Model inputs'!O111>'Model inputs'!O108),'Model inputs'!O111>'Model inputs'!O108,IF(OR('Model inputs'!O111="",'Model inputs'!O108=""),"",'Model inputs'!O111>'Model inputs'!O108))),('Model inputs'!O111-'Model inputs'!O108)*'Model inputs'!O89,0)) -> 0 | I21: ='Unit economics by plan (monthly'!I12*IF(IF(IF(IF(ISERROR('Model inputs'!O111>'Model inputs'!O108),'Model inputs'!O111>'Model inputs'!O108,IF(OR('Model inputs'!O111="",'Model inputs'!O108=""),"",'Model inputs'!O111>'Model inputs'!O108))="",FALSE,IF(ISERROR('Model inputs'!O111>'Model inputs'!O108),'Model inputs'!O111>'Model inputs'!O108,IF(OR('Model inputs'!O111="",'Model inputs'!O108=""),"",'Model inputs'!O111>'Model inputs'!O108))),('Model inputs'!O111-'Model inputs'!O108)*'Model inputs'!O89,0)="",0,IF(IF(IF(ISERROR('Model inputs'!O111>'Model inputs'!O108),'Model inputs'!O111>'Model inputs'!O108,IF(OR('Model inputs'!O111="",'Model inputs'!O108=""),"",'Model inputs'!O111>'Model inputs'!O108))="",FALSE,IF(ISERROR('Model inputs'!O111>'Model inputs'!O108),'Model inputs'!O111>'Model inputs'!O108,IF(OR('Model inputs'!O111="",'Model inputs'!O108=""),"",'Model inputs'!O111>'Model inputs'!O108))),('Model inputs'!O111-'Model inputs'!O108)*'Model inputs'!O89,0)) -> 0 | J21: ='Unit economics by plan (monthly'!J12*IF(IF(IF(IF(ISERROR('Model inputs'!O111>'Model inputs'!O108),'Model inputs'!O111>'Model inputs'!O108,IF(OR('Model inputs'!O111="",'Model inputs'!O108=""),"",'Model inputs'!O111>'Model inputs'!O108))="",FALSE,IF(ISERROR('Model inputs'!O111>'Model inputs'!O108),'Model inputs'!O111>'Model inputs'!O108,IF(OR('Model inputs'!O111="",'Model inputs'!O108=""),"",'Model inputs'!O111>'Model inputs'!O108))),('Model inputs'!O111-'Model inputs'!O108)*'Model inputs'!O89,0)="",0,IF(IF(IF(ISERROR('Model inputs'!O111>'Model inputs'!O108),'Model inputs'!O111>'Model inputs'!O108,IF(OR('Model inputs'!O111="",'Model inputs'!O108=""),"",'Model inputs'!O111>'Model inputs'!O108))="",FALSE,IF(ISERROR('Model inputs'!O111>'Model inputs'!O108),'Model inputs'!O111>'Model inputs'!O108,IF(OR('Model inputs'!O111="",'Model inputs'!O108=""),"",'Model inputs'!O111>'Model inputs'!O108))),('Model inputs'!O111-'Model inputs'!O108)*'Model inputs'!O89,0)) -> 0 | K21: ='Unit economics by plan (monthly'!K12*IF(IF(IF(IF(ISERROR('Model inputs'!O111>'Model inputs'!O108),'Model inputs'!O111>'Model inputs'!O108,IF(OR('Model inputs'!O111="",'Model inputs'!O108=""),"",'Model inputs'!O111>'Model inputs'!O108))="",FALSE,IF(ISERROR('Model inputs'!O111>'Model inputs'!O108),'Model inputs'!O111>'Model inputs'!O108,IF(OR('Model inputs'!O111="",'Model inputs'!O108=""),"",'Model inputs'!O111>'Model inputs'!O108))),('Model inputs'!O111-'Model inputs'!O108)*'Model inputs'!O89,0)="",0,IF(IF(IF(ISERROR('Model inputs'!O111>'Model inputs'!O108),'Model inputs'!O111>'Model inputs'!O108,IF(OR('Model inputs'!O111="",'Model inputs'!O108=""),"",'Model inputs'!O111>'Model inputs'!O108))="",FALSE,IF(ISERROR('Model inputs'!O111>'Model inputs'!O108),'Model inputs'!O111>'Model inputs'!O108,IF(OR('Model inputs'!O111="",'Model inputs'!O108=""),"",'Model inputs'!O111>'Model inputs'!O108))),('Model inputs'!O111-'Model inputs'!O108)*'Model inputs'!O89,0)) -> 0 | L21: ='Unit economics by plan (monthly'!L12*IF(IF(IF(IF(ISERROR('Model inputs'!O111>'Model inputs'!O108),'Model inputs'!O111>'Model inputs'!O108,IF(OR('Model inputs'!O111="",'Model inputs'!O108=""),"",'Model inputs'!O111>'Model inputs'!O108))="",FALSE,IF(ISERROR('Model inputs'!O111>'Model inputs'!O108),'Model inputs'!O111>'Model inputs'!O108,IF(OR('Model inputs'!O111="",'Model inputs'!O108=""),"",'Model inputs'!O111>'Model inputs'!O108))),('Model inputs'!O111-'Model inputs'!O108)*'Model inputs'!O89,0)="",0,IF(IF(IF(ISERROR('Model inputs'!O111>'Model inputs'!O108),'Model inputs'!O111>'Model inputs'!O108,IF(OR('Model inputs'!O111="",'Model inputs'!O108=""),"",'Model inputs'!O111>'Model inputs'!O108))="",FALSE,IF(ISERROR('Model inputs'!O111>'Model inputs'!O108),'Model inputs'!O111>'Model inputs'!O108,IF(OR('Model inputs'!O111="",'Model inputs'!O108=""),"",'Model inputs'!O111>'Model inputs'!O108))),('Model inputs'!O111-'Model inputs'!O108)*'Model inputs'!O89,0)) -> 0 | M21: ='Unit economics by plan (monthly'!M12*IF(IF(IF(IF(ISERROR('Model inputs'!O111>'Model inputs'!O108),'Model inputs'!O111>'Model inputs'!O108,IF(OR('Model inputs'!O111="",'Model inputs'!O108=""),"",'Model inputs'!O111>'Model inputs'!O108))="",FALSE,IF(ISERROR('Model inputs'!O111>'Model inputs'!O108),'Model inputs'!O111>'Model inputs'!O108,IF(OR('Model inputs'!O111="",'Model inputs'!O108=""),"",'Model inputs'!O111>'Model inputs'!O108))),('Model inputs'!O111-'Model inputs'!O108)*'Model inputs'!O89,0)="",0,IF(IF(IF(ISERROR('Model inputs'!O111>'Model inputs'!O108),'Model inputs'!O111>'Model inputs'!O108,IF(OR('Model inputs'!O111="",'Model inputs'!O108=""),"",'Model inputs'!O111>'Model inputs'!O108))="",FALSE,IF(ISERROR('Model inputs'!O111>'Model inputs'!O108),'Model inputs'!O111>'Model inputs'!O108,IF(OR('Model inputs'!O111="",'Model inputs'!O108=""),"",'Model inputs'!O111>'Model inputs'!O108))),('Model inputs'!O111-'Model inputs'!O108)*'Model inputs'!O89,0)) -> 0
A22: Household | B22: ='Unit economics by plan (monthly'!B13*IF(IF(IF(IF(ISERROR('Model inputs'!O112>'Model inputs'!O109),'Model inputs'!O112>'Model inputs'!O109,IF(OR('Model inputs'!O112="",'Model inputs'!O109=""),"",'Model inputs'!O112>'Model inputs'!O109))="",FALSE,IF(ISERROR('Model inputs'!O112>'Model inputs'!O109),'Model inputs'!O112>'Model inputs'!O109,IF(OR('Model inputs'!O112="",'Model inputs'!O109=""),"",'Model inputs'!O112>'Model inputs'!O109))),('Model inputs'!O112-'Model inputs'!O109)*'Model inputs'!O90,0)="",0,IF(IF(IF(ISERROR('Model inputs'!O112>'Model inputs'!O109),'Model inputs'!O112>'Model inputs'!O109,IF(OR('Model inputs'!O112="",'Model inputs'!O109=""),"",'Model inputs'!O112>'Model inputs'!O109))="",FALSE,IF(ISERROR('Model inputs'!O112>'Model inputs'!O109),'Model inputs'!O112>'Model inputs'!O109,IF(OR('Model inputs'!O112="",'Model inputs'!O109=""),"",'Model inputs'!O112>'Model inputs'!O109))),('Model inputs'!O112-'Model inputs'!O109)*'Model inputs'!O90,0)) -> 0 | C22: ='Unit economics by plan (monthly'!C13*IF(IF(IF(IF(ISERROR('Model inputs'!O112>'Model inputs'!O109),'Model inputs'!O112>'Model inputs'!O109,IF(OR('Model inputs'!O112="",'Model inputs'!O109=""),"",'Model inputs'!O112>'Model inputs'!O109))="",FALSE,IF(ISERROR('Model inputs'!O112>'Model inputs'!O109),'Model inputs'!O112>'Model inputs'!O109,IF(OR('Model inputs'!O112="",'Model inputs'!O109=""),"",'Model inputs'!O112>'Model inputs'!O109))),('Model inputs'!O112-'Model inputs'!O109)*'Model inputs'!O90,0)="",0,IF(IF(IF(ISERROR('Model inputs'!O112>'Model inputs'!O109),'Model inputs'!O112>'Model inputs'!O109,IF(OR('Model inputs'!O112="",'Model inputs'!O109=""),"",'Model inputs'!O112>'Model inputs'!O109))="",FALSE,IF(ISERROR('Model inputs'!O112>'Model inputs'!O109),'Model inputs'!O112>'Model inputs'!O109,IF(OR('Model inputs'!O112="",'Model inputs'!O109=""),"",'Model inputs'!O112>'Model inputs'!O109))),('Model inputs'!O112-'Model inputs'!O109)*'Model inputs'!O90,0)) -> 0 | D22: ='Unit economics by plan (monthly'!D13*IF(IF(IF(IF(ISERROR('Model inputs'!O112>'Model inputs'!O109),'Model inputs'!O112>'Model inputs'!O109,IF(OR('Model inputs'!O112="",'Model inputs'!O109=""),"",'Model inputs'!O112>'Model inputs'!O109))="",FALSE,IF(ISERROR('Model inputs'!O112>'Model inputs'!O109),'Model inputs'!O112>'Model inputs'!O109,IF(OR('Model inputs'!O112="",'Model inputs'!O109=""),"",'Model inputs'!O112>'Model inputs'!O109))),('Model inputs'!O112-'Model inputs'!O109)*'Model inputs'!O90,0)="",0,IF(IF(IF(ISERROR('Model inputs'!O112>'Model inputs'!O109),'Model inputs'!O112>'Model inputs'!O109,IF(OR('Model inputs'!O112="",'Model inputs'!O109=""),"",'Model inputs'!O112>'Model inputs'!O109))="",FALSE,IF(ISERROR('Model inputs'!O112>'Model inputs'!O109),'Model inputs'!O112>'Model inputs'!O109,IF(OR('Model inputs'!O112="",'Model inputs'!O109=""),"",'Model inputs'!O112>'Model inputs'!O109))),('Model inputs'!O112-'Model inputs'!O109)*'Model inputs'!O90,0)) -> 0 | E22: ='Unit economics by plan (monthly'!E13*IF(IF(IF(IF(ISERROR('Model inputs'!O112>'Model inputs'!O109),'Model inputs'!O112>'Model inputs'!O109,IF(OR('Model inputs'!O112="",'Model inputs'!O109=""),"",'Model inputs'!O112>'Model inputs'!O109))="",FALSE,IF(ISERROR('Model inputs'!O112>'Model inputs'!O109),'Model inputs'!O112>'Model inputs'!O109,IF(OR('Model inputs'!O112="",'Model inputs'!O109=""),"",'Model inputs'!O112>'Model inputs'!O109))),('Model inputs'!O112-'Model inputs'!O109)*'Model inputs'!O90,0)="",0,IF(IF(IF(ISERROR('Model inputs'!O112>'Model inputs'!O109),'Model inputs'!O112>'Model inputs'!O109,IF(OR('Model inputs'!O112="",'Model inputs'!O109=""),"",'Model inputs'!O112>'Model inputs'!O109))="",FALSE,IF(ISERROR('Model inputs'!O112>'Model inputs'!O109),'Model inputs'!O112>'Model inputs'!O109,IF(OR('Model inputs'!O112="",'Model inputs'!O109=""),"",'Model inputs'!O112>'Model inputs'!O109))),('Model inputs'!O112-'Model inputs'!O109)*'Model inputs'!O90,0)) -> 0 | F22: ='Unit economics by plan (monthly'!F13*IF(IF(IF(IF(ISERROR('Model inputs'!O112>'Model inputs'!O109),'Model inputs'!O112>'Model inputs'!O109,IF(OR('Model inputs'!O112="",'Model inputs'!O109=""),"",'Model inputs'!O112>'Model inputs'!O109))="",FALSE,IF(ISERROR('Model inputs'!O112>'Model inputs'!O109),'Model inputs'!O112>'Model inputs'!O109,IF(OR('Model inputs'!O112="",'Model inputs'!O109=""),"",'Model inputs'!O112>'Model inputs'!O109))),('Model inputs'!O112-'Model inputs'!O109)*'Model inputs'!O90,0)="",0,IF(IF(IF(ISERROR('Model inputs'!O112>'Model inputs'!O109),'Model inputs'!O112>'Model inputs'!O109,IF(OR('Model inputs'!O112="",'Model inputs'!O109=""),"",'Model inputs'!O112>'Model inputs'!O109))="",FALSE,IF(ISERROR('Model inputs'!O112>'Model inputs'!O109),'Model inputs'!O112>'Model inputs'!O109,IF(OR('Model inputs'!O112="",'Model inputs'!O109=""),"",'Model inputs'!O112>'Model inputs'!O109))),('Model inputs'!O112-'Model inputs'!O109)*'Model inputs'!O90,0)) -> 0 | G22: ='Unit economics by plan (monthly'!G13*IF(IF(IF(IF(ISERROR('Model inputs'!O112>'Model inputs'!O109),'Model inputs'!O112>'Model inputs'!O109,IF(OR('Model inputs'!O112="",'Model inputs'!O109=""),"",'Model inputs'!O112>'Model inputs'!O109))="",FALSE,IF(ISERROR('Model inputs'!O112>'Model inputs'!O109),'Model inputs'!O112>'Model inputs'!O109,IF(OR('Model inputs'!O112="",'Model inputs'!O109=""),"",'Model inputs'!O112>'Model inputs'!O109))),('Model inputs'!O112-'Model inputs'!O109)*'Model inputs'!O90,0)="",0,IF(IF(IF(ISERROR('Model inputs'!O112>'Model inputs'!O109),'Model inputs'!O112>'Model inputs'!O109,IF(OR('Model inputs'!O112="",'Model inputs'!O109=""),"",'Model inputs'!O112>'Model inputs'!O109))="",FALSE,IF(ISERROR('Model inputs'!O112>'Model inputs'!O109),'Model inputs'!O112>'Model inputs'!O109,IF(OR('Model inputs'!O112="",'Model inputs'!O109=""),"",'Model inputs'!O112>'Model inputs'!O109))),('Model inputs'!O112-'Model inputs'!O109)*'Model inputs'!O90,0)) -> 0 | H22: ='Unit economics by plan (monthly'!H13*IF(IF(IF(IF(ISERROR('Model inputs'!O112>'Model inputs'!O109),'Model inputs'!O112>'Model inputs'!O109,IF(OR('Model inputs'!O112="",'Model inputs'!O109=""),"",'Model inputs'!O112>'Model inputs'!O109))="",FALSE,IF(ISERROR('Model inputs'!O112>'Model inputs'!O109),'Model inputs'!O112>'Model inputs'!O109,IF(OR('Model inputs'!O112="",'Model inputs'!O109=""),"",'Model inputs'!O112>'Model inputs'!O109))),('Model inputs'!O112-'Model inputs'!O109)*'Model inputs'!O90,0)="",0,IF(IF(IF(ISERROR('Model inputs'!O112>'Model inputs'!O109),'Model inputs'!O112>'Model inputs'!O109,IF(OR('Model inputs'!O112="",'Model inputs'!O109=""),"",'Model inputs'!O112>'Model inputs'!O109))="",FALSE,IF(ISERROR('Model inputs'!O112>'Model inputs'!O109),'Model inputs'!O112>'Model inputs'!O109,IF(OR('Model inputs'!O112="",'Model inputs'!O109=""),"",'Model inputs'!O112>'Model inputs'!O109))),('Model inputs'!O112-'Model inputs'!O109)*'Model inputs'!O90,0)) -> 0 | I22: ='Unit economics by plan (monthly'!I13*IF(IF(IF(IF(ISERROR('Model inputs'!O112>'Model inputs'!O109),'Model inputs'!O112>'Model inputs'!O109,IF(OR('Model inputs'!O112="",'Model inputs'!O109=""),"",'Model inputs'!O112>'Model inputs'!O109))="",FALSE,IF(ISERROR('Model inputs'!O112>'Model inputs'!O109),'Model inputs'!O112>'Model inputs'!O109,IF(OR('Model inputs'!O112="",'Model inputs'!O109=""),"",'Model inputs'!O112>'Model inputs'!O109))),('Model inputs'!O112-'Model inputs'!O109)*'Model inputs'!O90,0)="",0,IF(IF(IF(ISERROR('Model inputs'!O112>'Model inputs'!O109),'Model inputs'!O112>'Model inputs'!O109,IF(OR('Model inputs'!O112="",'Model inputs'!O109=""),"",'Model inputs'!O112>'Model inputs'!O109))="",FALSE,IF(ISERROR('Model inputs'!O112>'Model inputs'!O109),'Model inputs'!O112>'Model inputs'!O109,IF(OR('Model inputs'!O112="",'Model inputs'!O109=""),"",'Model inputs'!O112>'Model inputs'!O109))),('Model inputs'!O112-'Model inputs'!O109)*'Model inputs'!O90,0)) -> 0 | J22: ='Unit economics by plan (monthly'!J13*IF(IF(IF(IF(ISERROR('Model inputs'!O112>'Model inputs'!O109),'Model inputs'!O112>'Model inputs'!O109,IF(OR('Model inputs'!O112="",'Model inputs'!O109=""),"",'Model inputs'!O112>'Model inputs'!O109))="",FALSE,IF(ISERROR('Model inputs'!O112>'Model inputs'!O109),'Model inputs'!O112>'Model inputs'!O109,IF(OR('Model inputs'!O112="",'Model inputs'!O109=""),"",'Model inputs'!O112>'Model inputs'!O109))),('Model inputs'!O112-'Model inputs'!O109)*'Model inputs'!O90,0)="",0,IF(IF(IF(ISERROR('Model inputs'!O112>'Model inputs'!O109),'Model inputs'!O112>'Model inputs'!O109,IF(OR('Model inputs'!O112="",'Model inputs'!O109=""),"",'Model inputs'!O112>'Model inputs'!O109))="",FALSE,IF(ISERROR('Model inputs'!O112>'Model inputs'!O109),'Model inputs'!O112>'Model inputs'!O109,IF(OR('Model inputs'!O112="",'Model inputs'!O109=""),"",'Model inputs'!O112>'Model inputs'!O109))),('Model inputs'!O112-'Model inputs'!O109)*'Model inputs'!O90,0)) -> 0 | K22: ='Unit economics by plan (monthly'!K13*IF(IF(IF(IF(ISERROR('Model inputs'!O112>'Model inputs'!O109),'Model inputs'!O112>'Model inputs'!O109,IF(OR('Model inputs'!O112="",'Model inputs'!O109=""),"",'Model inputs'!O112>'Model inputs'!O109))="",FALSE,IF(ISERROR('Model inputs'!O112>'Model inputs'!O109),'Model inputs'!O112>'Model inputs'!O109,IF(OR('Model inputs'!O112="",'Model inputs'!O109=""),"",'Model inputs'!O112>'Model inputs'!O109))),('Model inputs'!O112-'Model inputs'!O109)*'Model inputs'!O90,0)="",0,IF(IF(IF(ISERROR('Model inputs'!O112>'Model inputs'!O109),'Model inputs'!O112>'Model inputs'!O109,IF(OR('Model inputs'!O112="",'Model inputs'!O109=""),"",'Model inputs'!O112>'Model inputs'!O109))="",FALSE,IF(ISERROR('Model inputs'!O112>'Model inputs'!O109),'Model inputs'!O112>'Model inputs'!O109,IF(OR('Model inputs'!O112="",'Model inputs'!O109=""),"",'Model inputs'!O112>'Model inputs'!O109))),('Model inputs'!O112-'Model inputs'!O109)*'Model inputs'!O90,0)) -> 0 | L22: ='Unit economics by plan (monthly'!L13*IF(IF(IF(IF(ISERROR('Model inputs'!O112>'Model inputs'!O109),'Model inputs'!O112>'Model inputs'!O109,IF(OR('Model inputs'!O112="",'Model inputs'!O109=""),"",'Model inputs'!O112>'Model inputs'!O109))="",FALSE,IF(ISERROR('Model inputs'!O112>'Model inputs'!O109),'Model inputs'!O112>'Model inputs'!O109,IF(OR('Model inputs'!O112="",'Model inputs'!O109=""),"",'Model inputs'!O112>'Model inputs'!O109))),('Model inputs'!O112-'Model inputs'!O109)*'Model inputs'!O90,0)="",0,IF(IF(IF(ISERROR('Model inputs'!O112>'Model inputs'!O109),'Model inputs'!O112>'Model inputs'!O109,IF(OR('Model inputs'!O112="",'Model inputs'!O109=""),"",'Model inputs'!O112>'Model inputs'!O109))="",FALSE,IF(ISERROR('Model inputs'!O112>'Model inputs'!O109),'Model inputs'!O112>'Model inputs'!O109,IF(OR('Model inputs'!O112="",'Model inputs'!O109=""),"",'Model inputs'!O112>'Model inputs'!O109))),('Model inputs'!O112-'Model inputs'!O109)*'Model inputs'!O90,0)) -> 0 | M22: ='Unit economics by plan (monthly'!M13*IF(IF(IF(IF(ISERROR('Model inputs'!O112>'Model inputs'!O109),'Model inputs'!O112>'Model inputs'!O109,IF(OR('Model inputs'!O112="",'Model inputs'!O109=""),"",'Model inputs'!O112>'Model inputs'!O109))="",FALSE,IF(ISERROR('Model inputs'!O112>'Model inputs'!O109),'Model inputs'!O112>'Model inputs'!O109,IF(OR('Model inputs'!O112="",'Model inputs'!O109=""),"",'Model inputs'!O112>'Model inputs'!O109))),('Model inputs'!O112-'Model inputs'!O109)*'Model inputs'!O90,0)="",0,IF(IF(IF(ISERROR('Model inputs'!O112>'Model inputs'!O109),'Model inputs'!O112>'Model inputs'!O109,IF(OR('Model inputs'!O112="",'Model inputs'!O109=""),"",'Model inputs'!O112>'Model inputs'!O109))="",FALSE,IF(ISERROR('Model inputs'!O112>'Model inputs'!O109),'Model inputs'!O112>'Model inputs'!O109,IF(OR('Model inputs'!O112="",'Model inputs'!O109=""),"",'Model inputs'!O112>'Model inputs'!O109))),('Model inputs'!O112-'Model inputs'!O109)*'Model inputs'!O90,0)) -> 0
A23: Revenue (USD) | B23: =SUM('Unit economics by plan (monthly'!B24,'Unit economics by plan (monthly'!B25) -> 623.452 | C23: =SUM('Unit economics by plan (monthly'!C24,'Unit economics by plan (monthly'!C25) -> 674.01084 | D23: =SUM('Unit economics by plan (monthly'!D24,'Unit economics by plan (monthly'!D25) -> 721.50952 | E23: =SUM('Unit economics by plan (monthly'!E24,'Unit economics by plan (monthly'!E25) -> 766.16332 | F23: =SUM('Unit economics by plan (monthly'!F24,'Unit economics by plan (monthly'!F25) -> 808.17119 | G23: =SUM('Unit economics by plan (monthly'!G24,'Unit economics by plan (monthly'!G25) -> 847.71699 | H23: =SUM('Unit economics by plan (monthly'!H24,'Unit economics by plan (monthly'!H25) -> 884.97074 | I23: =SUM('Unit economics by plan (monthly'!I24,'Unit economics by plan (monthly'!I25) -> 920.08966 | ... M23: =SUM('Unit economics by plan (monthly'!M24,'Unit economics by plan (monthly'!M25) -> 1041.9674
A24: Classroom | B24: ='Unit economics by plan (monthly'!B18+'Unit economics by plan (monthly'!B21 -> 310.3 | C24: ='Unit economics by plan (monthly'!C18+'Unit economics by plan (monthly'!C21 -> 329.991 | D24: ='Unit economics by plan (monthly'!D18+'Unit economics by plan (monthly'!D21 -> 349.09127 | E24: ='Unit economics by plan (monthly'!E18+'Unit economics by plan (monthly'!E21 -> 367.61853 | F24: ='Unit economics by plan (monthly'!F18+'Unit economics by plan (monthly'!F21 -> 385.58998 | G24: ='Unit economics by plan (monthly'!G18+'Unit economics by plan (monthly'!G21 -> 403.02228 | H24: ='Unit economics by plan (monthly'!H18+'Unit economics by plan (monthly'!H21 -> 419.93161 | I24: ='Unit economics by plan (monthly'!I18+'Unit economics by plan (monthly'!I21 -> 436.33366 | ... M24: ='Unit economics by plan (monthly'!M18+'Unit economics by plan (monthly'!M21 -> 497.16667
A25: Household | B25: ='Unit economics by plan (monthly'!B19+'Unit economics by plan (monthly'!B22 -> 313.152 | C25: ='Unit economics by plan (monthly'!C19+'Unit economics by plan (monthly'!C22 -> 344.01984 | D25: ='Unit economics by plan (monthly'!D19+'Unit economics by plan (monthly'!D22 -> 372.41825 | E25: ='Unit economics by plan (monthly'!E19+'Unit economics by plan (monthly'!E22 -> 398.54479 | F25: ='Unit economics by plan (monthly'!F19+'Unit economics by plan (monthly'!F22 -> 422.58121 | G25: ='Unit economics by plan (monthly'!G19+'Unit economics by plan (monthly'!G22 -> 444.69471 | H25: ='Unit economics by plan (monthly'!H19+'Unit economics by plan (monthly'!H22 -> 465.03914 | I25: ='Unit economics by plan (monthly'!I19+'Unit economics by plan (monthly'!I22 -> 483.756 | ... M25: ='Unit economics by plan (monthly'!M19+'Unit economics by plan (monthly'!M22 -> 544.80072
A26: Inference cost (USD, estimate) | B26: =SUM('Unit economics by plan (monthly'!B27,'Unit economics by plan (monthly'!B28) -> 188.9573 | C26: =SUM('Unit economics by plan (monthly'!C27,'Unit economics by plan (monthly'!C28) -> 203.16695 | D26: =SUM('Unit economics by plan (monthly'!D27,'Unit economics by plan (monthly'!D28) -> 216.63887 | E26: =SUM('Unit economics by plan (monthly'!E27,'Unit economics by plan (monthly'!E28) -> 229.42012 | F26: =SUM('Unit economics by plan (monthly'!F27,'Unit economics by plan (monthly'!F28) -> 241.55433 | G26: =SUM('Unit economics by plan (monthly'!G27,'Unit economics by plan (monthly'!G28) -> 253.082 | H26: =SUM('Unit economics by plan (monthly'!H27,'Unit economics by plan (monthly'!H28) -> 264.04074 | I26: =SUM('Unit economics by plan (monthly'!I27,'Unit economics by plan (monthly'!I28) -> 274.46545 | ... M26: =SUM('Unit economics by plan (monthly'!M27,'Unit economics by plan (monthly'!M28) -> 311.43963
A27: Classroom | B27: ='Unit economics by plan (monthly'!B15*'Model inputs'!O18 -> 125.7678 | C27: ='Unit economics by plan (monthly'!C15*'Model inputs'!O18 -> 133.74877 | D27: ='Unit economics by plan (monthly'!D15*'Model inputs'!O18 -> 141.4903 | E27: ='Unit economics by plan (monthly'!E15*'Model inputs'!O18 -> 148.99959 | F27: ='Unit economics by plan (monthly'!F15*'Model inputs'!O18 -> 156.28361 | G27: ='Unit economics by plan (monthly'!G15*'Model inputs'!O18 -> 163.3491 | H27: ='Unit economics by plan (monthly'!H15*'Model inputs'!O18 -> 170.20262 | I27: ='Unit economics by plan (monthly'!I15*'Model inputs'!O18 -> 176.85055 | J27: ='Unit economics by plan (monthly'!J15*'Model inputs'!O18 -> 183.29903 | K27: ='Unit economics by plan (monthly'!K15*'Model inputs'!O18 -> 189.55406 | L27: ='Unit economics by plan (monthly'!L15*'Model inputs'!O18 -> 195.62144 | M27: ='Unit economics by plan (monthly'!M15*'Model inputs'!O18 -> 201.50679
A28: Household | B28: ='Unit economics by plan (monthly'!B16*'Model inputs'!O18 -> 63.189504 | C28: ='Unit economics by plan (monthly'!C16*'Model inputs'!O18 -> 69.418184 | D28: ='Unit economics by plan (monthly'!D16*'Model inputs'!O18 -> 75.148569 | E28: ='Unit economics by plan (monthly'!E16*'Model inputs'!O18 -> 80.420523 | F28: ='Unit economics by plan (monthly'!F16*'Model inputs'!O18 -> 85.270722 | G28: ='Unit economics by plan (monthly'!G16*'Model inputs'!O18 -> 89.732904 | H28: ='Unit economics by plan (monthly'!H16*'Model inputs'!O18 -> 93.838112 | I28: ='Unit economics by plan (monthly'!I16*'Model inputs'!O18 -> 97.614903 | J28: ='Unit economics by plan (monthly'!J16*'Model inputs'!O18 -> 101.08955 | K28: ='Unit economics by plan (monthly'!K16*'Model inputs'!O18 -> 104.28623 | L28: ='Unit economics by plan (monthly'!L16*'Model inputs'!O18 -> 107.22717 | M28: ='Unit economics by plan (monthly'!M16*'Model inputs'!O18 -> 109.93283

Sheet Gross profit and margin by plan
A1: Gross profit and margin by plan (monthly)
A2: Unit economics · Main Scenario
A4: Variable / dimension | B4: 2026-10 | C4: 2026-11 | D4: 2026-12 | E4: 2027-01 | F4: 2027-02 | G4: 2027-03 | H4: 2027-04 | I4: 2027-05 | J4: 2027-06 | K4: 2027-07 | L4: 2027-08 | M4: 2027-09
A5: Spans per month (derived) | B5: ='Unit economics by plan (monthly'!B14*'Model inputs'!O106 -> 144684 | C5: ='Unit economics by plan (monthly'!C14*'Model inputs'!O106 -> 155564.28 | D5: ='Unit economics by plan (monthly'!D14*'Model inputs'!O106 -> 165879.69 | E5: ='Unit economics by plan (monthly'!E14*'Model inputs'!O106 -> 175666.25 | F5: ='Unit economics by plan (monthly'!F14*'Model inputs'!O106 -> 184957.37 | G5: ='Unit economics by plan (monthly'!G14*'Model inputs'!O106 -> 193784.07 | H5: ='Unit economics by plan (monthly'!H14*'Model inputs'!O106 -> 202175.14 | I5: ='Unit economics by plan (monthly'!I14*'Model inputs'!O106 -> 210157.31 | J5: ='Unit economics by plan (monthly'!J14*'Model inputs'!O106 -> 217755.42 | K5: ='Unit economics by plan (monthly'!K14*'Model inputs'!O106 -> 224992.56 | L5: ='Unit economics by plan (monthly'!L14*'Model inputs'!O106 -> 231890.2 | M5: ='Unit economics by plan (monthly'!M14*'Model inputs'!O106 -> 238468.32
