Workbook

Sheet Verification and illustration p
A1: Verification and illustration policy: cost, margin and bar
A2: Verification and illustration policy · Main Scenario
A4: Variable / dimension | B4: Full (8 pictures) | C4: Half (4 pictures) | D4: Text only (0)
A5: Cost per story (USD, estimate) | B5: ="" | C5: ="" | D5: =""
A6: Sampled | B6: ='Model inputs'!C36+'Model inputs'!C15+'Model inputs'!C38 -> 0.35284 | C6: ='Model inputs'!C36+'Model inputs'!C16+'Model inputs'!C38 -> 0.19284 | D6: ='Model inputs'!C36+'Model inputs'!C17+'Model inputs'!C38 -> 0.03284
A7: Verify all | B7: ='Model inputs'!C37+'Model inputs'!C15+'Model inputs'!C38 -> 0.3559 | C7: ='Model inputs'!C37+'Model inputs'!C16+'Model inputs'!C38 -> 0.1959 | D7: ='Model inputs'!C37+'Model inputs'!C17+'Model inputs'!C38 -> 0.0359
A8: Gross margin at month 6 (derived) | B8: ="" | C8: ="" | D8: =""
A9: Sampled | B9: =IFERROR(('Month 6 reference (company, sel'!B5-'Month 6 reference (company, sel'!B7-'Month 6 reference (company, sel'!B6*'Verification and illustration p'!B6)/'Month 6 reference (company, sel'!B5,0) -> 0.43279204 | C9: =IFERROR(('Month 6 reference (company, sel'!B5-'Month 6 reference (company, sel'!B7-'Month 6 reference (company, sel'!B6*'Verification and illustration p'!C6)/'Month 6 reference (company, sel'!B5,0) -> 0.67662698 | D9: =IFERROR(('Month 6 reference (company, sel'!B5-'Month 6 reference (company, sel'!B7-'Month 6 reference (company, sel'!B6*'Verification and illustration p'!D6)/'Month 6 reference (company, sel'!B5,0) -> 0.92046191
A10: Verify all | B10: =IFERROR(('Month 6 reference (company, sel'!B5-'Month 6 reference (company, sel'!B7-'Month 6 reference (company, sel'!B6*'Verification and illustration p'!B7)/'Month 6 reference (company, sel'!B5,0) -> 0.4281287 | C10: =IFERROR(('Month 6 reference (company, sel'!B5-'Month 6 reference (company, sel'!B7-'Month 6 reference (company, sel'!B6*'Verification and illustration p'!C7)/'Month 6 reference (company, sel'!B5,0) -> 0.67196363 | D10: =IFERROR(('Month 6 reference (company, sel'!B5-'Month 6 reference (company, sel'!B7-'Month 6 reference (company, sel'!B6*'Verification and illustration p'!D7)/'Month 6 reference (company, sel'!B5,0) -> 0.91579856
A11: Clears the gross margin bar at month 6 (1 = yes) | B11: ="" | C11: ="" | D11: =""
A12: Sampled | B12: =IF(IF(IF(ISERROR('Verification and illustration p'!B9>='Model inputs'!C7),'Verification and illustration p'!B9>='Model inputs'!C7,IF(OR('Verification and illustration p'!B9="",'Model inputs'!C7=""),"",'Verification and illustration p'!B9>='Model inputs'!C7))="",FALSE,IF(ISERROR('Verification and illustration p'!B9>='Model inputs'!C7),'Verification and illustration p'!B9>='Model inputs'!C7,IF(OR('Verification and illustration p'!B9="",'Model inputs'!C7=""),"",'Verification and illustration p'!B9>='Model inputs'!C7))),1,0) -> 0 | C12: =IF(IF(IF(ISERROR('Verification and illustration p'!C9>='Model inputs'!C7),'Verification and illustration p'!C9>='Model inputs'!C7,IF(OR('Verification and illustration p'!C9="",'Model inputs'!C7=""),"",'Verification and illustration p'!C9>='Model inputs'!C7))="",FALSE,IF(ISERROR('Verification and illustration p'!C9>='Model inputs'!C7),'Verification and illustration p'!C9>='Model inputs'!C7,IF(OR('Verification and illustration p'!C9="",'Model inputs'!C7=""),"",'Verification and illustration p'!C9>='Model inputs'!C7))),1,0) -> 1 | D12: =IF(IF(IF(ISERROR('Verification and illustration p'!D9>='Model inputs'!C7),'Verification and illustration p'!D9>='Model inputs'!C7,IF(OR('Verification and illustration p'!D9="",'Model inputs'!C7=""),"",'Verification and illustration p'!D9>='Model inputs'!C7))="",FALSE,IF(ISERROR('Verification and illustration p'!D9>='Model inputs'!C7),'Verification and illustration p'!D9>='Model inputs'!C7,IF(OR('Verification and illustration p'!D9="",'Model inputs'!C7=""),"",'Verification and illustration p'!D9>='Model inputs'!C7))),1,0) -> 1
A13: Verify all | B13: =IF(IF(IF(ISERROR('Verification and illustration p'!B10>='Model inputs'!C7),'Verification and illustration p'!B10>='Model inputs'!C7,IF(OR('Verification and illustration p'!B10="",'Model inputs'!C7=""),"",'Verification and illustration p'!B10>='Model inputs'!C7))="",FALSE,IF(ISERROR('Verification and illustration p'!B10>='Model inputs'!C7),'Verification and illustration p'!B10>='Model inputs'!C7,IF(OR('Verification and illustration p'!B10="",'Model inputs'!C7=""),"",'Verification and illustration p'!B10>='Model inputs'!C7))),1,0) -> 0 | C13: =IF(IF(IF(ISERROR('Verification and illustration p'!C10>='Model inputs'!C7),'Verification and illustration p'!C10>='Model inputs'!C7,IF(OR('Verification and illustration p'!C10="",'Model inputs'!C7=""),"",'Verification and illustration p'!C10>='Model inputs'!C7))="",FALSE,IF(ISERROR('Verification and illustration p'!C10>='Model inputs'!C7),'Verification and illustration p'!C10>='Model inputs'!C7,IF(OR('Verification and illustration p'!C10="",'Model inputs'!C7=""),"",'Verification and illustration p'!C10>='Model inputs'!C7))),1,0) -> 1 | D13: =IF(IF(IF(ISERROR('Verification and illustration p'!D10>='Model inputs'!C7),'Verification and illustration p'!D10>='Model inputs'!C7,IF(OR('Verification and illustration p'!D10="",'Model inputs'!C7=""),"",'Verification and illustration p'!D10>='Model inputs'!C7))="",FALSE,IF(ISERROR('Verification and illustration p'!D10>='Model inputs'!C7),'Verification and illustration p'!D10>='Model inputs'!C7,IF(OR('Verification and illustration p'!D10="",'Model inputs'!C7=""),"",'Verification and illustration p'!D10>='Model inputs'!C7))),1,0) -> 1
A14: Headroom under the per-story budget (USD, derived) | B14: ="" | C14: ="" | D14: =""
A15: Sampled | B15: ='Month 6 reference (company, sel'!B8-'Verification and illustration p'!B6 -> -0.10971879 | C15: ='Month 6 reference (company, sel'!B8-'Verification and illustration p'!C6 -> 0.050281213 | D15: ='Month 6 reference (company, sel'!B8-'Verification and illustration p'!D6 -> 0.21028121
A16: Verify all | B16: ='Month 6 reference (company, sel'!B8-'Verification and illustration p'!B7 -> -0.11277879 | C16: ='Month 6 reference (company, sel'!B8-'Verification and illustration p'!C7 -> 0.047221213 | D16: ='Month 6 reference (company, sel'!B8-'Verification and illustration p'!D7 -> 0.20722121

Sheet Month 6 reference (company, sel
A1: Month 6 reference (company, selected policy)
A2: Verification and illustration policy · Main Scenario
A4: Variable / dimension | B4: Value
A5: Revenue at month 6 (USD, derived) | B5: =SUM('Model inputs'!B19,'Model inputs'!B20) -> 847.71699
A6: Stories delivered at month 6 (derived) | B6: =SUM('Model inputs'!B31,'Model inputs'!B32) -> 1291.8938
A7: Hosting and neatlogs at month 6 (USD, derived) | B7: ='Model inputs'!D11+'Model inputs'!B12 -> 25
A8: Per-story budget that clears the bar at month 6 (USD, derived) | B8: =IFERROR(('Month 6 reference (company, sel'!B5*(1-'Model inputs'!C7)-'Month 6 reference (company, sel'!B7)/'Month 6 reference (company, sel'!B6,0) -> 0.24312121
A9: Gross margin at month 6, selected policy (monthly table) | B9: =IF('Model inputs'!B6="","",'Model inputs'!B6) -> 0.67196363
A10: Gross margin at month 6, selected policy (policy arithmetic) | B10: =IFERROR(('Month 6 reference (company, sel'!B5-'Month 6 reference (company, sel'!B7-'Month 6 reference (company, sel'!B6*'Selected policy'!B5)/'Month 6 reference (company, sel'!B5,0) -> 0.67196363
A11: Reconciliation difference (should be 0) | B11: ='Month 6 reference (company, sel'!B9-'Month 6 reference (company, sel'!B10 -> 0

Sheet Selected policy
A1: Selected policy
A2: Verification and illustration policy · Main Scenario
A4: Variable / dimension | B4: Value
A5: Cost per story, selected policy (USD, estimate) | B5: =SUM('Model inputs'!D28,'Model inputs'!D29)+SUM('Model inputs'!D24,'Model inputs'!D25,'Model inputs'!D26) -> 0.1959

Sheet Model inputs
A1: Model inputs
A2: Integration values are aggregated snapshots; raw source records are not included.
A4: Variables
A5: Variable / segment | B5: 2027-03 | C5: Value | D5: Value | E5: 2026-09 | F5: 2026-10 | G5: 2026-11 | H5: 2026-12 | I5: 2027-01 | J5: 2027-02 | K5: 2027-04 | L5: 2027-05 | M5: 2027-06 | N5: 2027-07 | O5: 2027-08 | P5: 2027-09
A6: Gross margin | B6: =IFERROR('Model inputs'!B50/'Model inputs'!B18,0) -> 0.67196363
A7: Gross margin bar (ours, stated) · Verification and illustration policy: cost, margin and bar | C7: =0.6 -> 0.6
A8: Gross margin bar (ours, stated) · Month 6 reference (company, selected policy) | D8: ='Model inputs'!C7 -> 0.6
A9: Hosting and neatlogs at month 6 (USD, derived) · Verification and illustration policy: cost, margin and bar | C9: ='Model inputs'!D11+'Model inputs'!B12 -> 25
A10: Hosting and neatlogs at month 6 (USD, derived) · Month 6 reference (company, selected policy) | D10: ='Model inputs'!D11+'Model inputs'!B12 -> 25
A11: Hosting per month (USD, assumed) · Month 6 reference (company, selected policy) | D11: =25 -> 25
A12: neatlogs bill (USD, derived) · Month 6 reference (company, selected policy) | B12: =IF(IF(IF(ISERROR('Model inputs'!C55=1),'Model inputs'!C55=1,IF('Model inputs'!C55="","",'Model inputs'!C55=1))="",FALSE,IF(ISERROR('Model inputs'!C55=1),'Model inputs'!C55=1,IF('Model inputs'!C55="","",'Model inputs'!C55=1))),0,IF(IF(IF(ISERROR('Model inputs'!B75<='Model inputs'!C56),'Model inputs'!B75<='Model inputs'!C56,IF(OR('Model inputs'!B75="",'Model inputs'!C56=""),"",'Model inputs'!B75<='Model inputs'!C56))="",FALSE,IF(ISERROR('Model inputs'!B75<='Model inputs'!C56),'Model inputs'!B75<='Model inputs'!C56,IF(OR('Model inputs'!B75="",'Model inputs'!C56=""),"",'Model inputs'!B75<='Model inputs'!C56))),0,IF(IF(IF(ISERROR('Model inputs'!B75<='Model inputs'!C58),'Model inputs'!B75<='Model inputs'!C58,IF(OR('Model inputs'!B75="",'Model inputs'!C58=""),"",'Model inputs'!B75<='Model inputs'!C58))="",FALSE,IF(ISERROR('Model inputs'!B75<='Model inputs'!C58),'Model inputs'!B75<='Model inputs'!C58,IF(OR('Model inputs'!B75="",'Model inputs'!C58=""),"",'Model inputs'!B75<='Model inputs'!C58))),IF('Model inputs'!C59="","",'Model inputs'!C59),'Model inputs'!C59+CEILING(('Model inputs'!B75-'Model inputs'!C58)/100000,1)*'Model inputs'!C57))) -> 0
A13: Per-story budget that clears the bar at month 6 (USD, derived) | C13: =IFERROR(('Model inputs'!C21*(1-'Model inputs'!C7)-'Model inputs'!C9)/'Model inputs'!C33,0) -> 0.24312121
A14: Picture and narration cost per story (USD, derived) | C14: ='Model inputs'!C67*'Model inputs'!C43+'Model inputs'!C41*'Model inputs'!C42 -> 0.016
A15: Picture and narration cost per story (USD, derived) > Full (8 pictures) | C15: ='Model inputs'!C68*'Model inputs'!C43+'Model inputs'!C41*'Model inputs'!C42 -> 0.336
A16: Picture and narration cost per story (USD, derived) > Half (4 pictures) | C16: ='Model inputs'!C69*'Model inputs'!C43+'Model inputs'!C41*'Model inputs'!C42 -> 0.176
A17: Picture and narration cost per story (USD, derived) > Text only (0) | C17: ='Model inputs'!C70*'Model inputs'!C43+'Model inputs'!C41*'Model inputs'!C42 -> 0.016
A18: Revenue (USD) | B18: =SUM('Model inputs'!B19,'Model inputs'!B20) -> 847.71699 | E18: =SUM('Model inputs'!E19,'Model inputs'!E20) -> 0 | F18: =SUM('Model inputs'!F19,'Model inputs'!F20) -> 623.452 | G18: =SUM('Model inputs'!G19,'Model inputs'!G20) -> 674.01084 | H18: =SUM('Model inputs'!H19,'Model inputs'!H20) -> 721.50952 | I18: =SUM('Model inputs'!I19,'Model inputs'!I20) -> 766.16332 | J18: =SUM('Model inputs'!J19,'Model inputs'!J20) -> 808.17119 | K18: =SUM('Model inputs'!K19,'Model inputs'!K20) -> 884.97074 | L18: =SUM('Model inputs'!L19,'Model inputs'!L20) -> 920.08966 | ... P18: =SUM('Model inputs'!P19,'Model inputs'!P20) -> 1041.9674
A19: Revenue (USD) > Classroom | B19: ='Model inputs'!B80+'Model inputs'!B61 -> 403.02228 | E19: =0 -> 0 | F19: ='Model inputs'!F80+'Model inputs'!F61 -> 310.3 | G19: ='Model inputs'!G80+'Model inputs'!G61 -> 329.991 | H19: ='Model inputs'!H80+'Model inputs'!H61 -> 349.09127 | I19: ='Model inputs'!I80+'Model inputs'!I61 -> 367.61853 | J19: ='Model inputs'!J80+'Model inputs'!J61 -> 385.58998 | K19: ='Model inputs'!K80+'Model inputs'!K61 -> 419.93161 | L19: ='Model inputs'!L80+'Model inputs'!L61 -> 436.33366 | M19: ='Model inputs'!M80+'Model inputs'!M61 -> 452.24365 | ... P19: ='Model inputs'!P80+'Model inputs'!P61 -> 497.16667
A20: Revenue (USD) > Household | B20: ='Model inputs'!B81+'Model inputs'!B62 -> 444.69471 | E20: =0 -> 0 | F20: ='Model inputs'!F81+'Model inputs'!F62 -> 313.152 | G20: ='Model inputs'!G81+'Model inputs'!G62 -> 344.01984 | H20: ='Model inputs'!H81+'Model inputs'!H62 -> 372.41825 | I20: ='Model inputs'!I81+'Model inputs'!I62 -> 398.54479 | J20: ='Model inputs'!J81+'Model inputs'!J62 -> 422.58121 | K20: ='Model inputs'!K81+'Model inputs'!K62 -> 465.03914 | L20: ='Model inputs'!L81+'Model inputs'!L62 -> 483.756 | M20: ='Model inputs'!M81+'Model inputs'!M62 -> 500.97552 | ... P20: ='Model inputs'!P81+'Model inputs'!P62 -> 544.80072
A21: Revenue at month 6 (USD, derived) · Verification and illustration policy: cost, margin and bar | C21: =SUM('Model inputs'!B19,'Model inputs'!B20) -> 847.71699
A22: Revenue at month 6 (USD, derived) · Month 6 reference (company, selected policy) | D22: =SUM('Model inputs'!B19,'Model inputs'!B20) -> 847.71699
A23: Selected picture and narration cost (USD, derived) | D23: ='Model inputs'!C14*'Model inputs'!D51 -> 0
A24: Selected picture and narration cost (USD, derived) > Full (8 pictures) | D24: ='Model inputs'!C15*'Model inputs'!D52 -> 0
A25: Selected picture and narration cost (USD, derived) > Half (4 pictures) | D25: ='Model inputs'!C16*'Model inputs'!D53 -> 0.176
A26: Selected picture and narration cost (USD, derived) > Text only (0) | D26: ='Model inputs'!C17*'Model inputs'!D54 -> 0
A27: Selected text and verification cost (USD, derived) | D27: ='Model inputs'!C35*'Model inputs'!D85 -> 0
A28: Selected text and verification cost (USD, derived) > Sampled | D28: ='Model inputs'!C36*'Model inputs'!D86 -> 0
A29: Selected text and verification cost (USD, derived) > Verify all | D29: ='Model inputs'!C37*'Model inputs'!D87 -> 0.0199
A30: Stories delivered | B30: =SUM('Model inputs'!B31,'Model inputs'!B32) -> 1291.8938 | E30: =SUM('Model inputs'!E31,'Model inputs'!E32) -> 0 | F30: =SUM('Model inputs'!F31,'Model inputs'!F32) -> 964.56 | G30: =SUM('Model inputs'!G31,'Model inputs'!G32) -> 1037.0952 | H30: =SUM('Model inputs'!H31,'Model inputs'!H32) -> 1105.8646 | I30: =SUM('Model inputs'!I31,'Model inputs'!I32) -> 1171.1083 | J30: =SUM('Model inputs'!J31,'Model inputs'!J32) -> 1233.0491 | K30: =SUM('Model inputs'!K31,'Model inputs'!K32) -> 1347.8343 | L30: =SUM('Model inputs'!L31,'Model inputs'!L32) -> 1401.0487 | ... P30: =SUM('Model inputs'!P31,'Model inputs'!P32) -> 1589.7888
A31: Stories delivered > Classroom | B31: ='Model inputs'!B48*'Model inputs'!C77 -> 833.83919 | E31: =0 -> 0 | F31: ='Model inputs'!F48*'Model inputs'!C77 -> 642 | G31: ='Model inputs'!G48*'Model inputs'!C77 -> 682.74 | H31: ='Model inputs'!H48*'Model inputs'!C77 -> 722.2578 | I31: ='Model inputs'!I48*'Model inputs'!C77 -> 760.59007 | J31: ='Model inputs'!J48*'Model inputs'!C77 -> 797.77236 | K31: ='Model inputs'!K48*'Model inputs'!C77 -> 868.82402 | L31: ='Model inputs'!L48*'Model inputs'!C77 -> 902.7593 | M31: ='Model inputs'!M48*'Model inputs'!C77 -> 935.67652 | N31: ='Model inputs'!N48*'Model inputs'!C77 -> 967.60622 | O31: ='Model inputs'!O48*'Model inputs'!C77 -> 998.57804 | P31: ='Model inputs'!P48*'Model inputs'!C77 -> 1028.6207
A32: Stories delivered > Household | B32: ='Model inputs'!B49*'Model inputs'!C78 -> 458.05464 | E32: =0 -> 0 | F32: ='Model inputs'!F49*'Model inputs'!C78 -> 322.56 | G32: ='Model inputs'!G49*'Model inputs'!C78 -> 354.3552 | H32: ='Model inputs'!H49*'Model inputs'!C78 -> 383.60678 | I32: ='Model inputs'!I49*'Model inputs'!C78 -> 410.51824 | J32: ='Model inputs'!J49*'Model inputs'!C78 -> 435.27678 | K32: ='Model inputs'!K49*'Model inputs'!C78 -> 479.01027 | L32: ='Model inputs'!L49*'Model inputs'!C78 -> 498.28945 | M32: ='Model inputs'!M49*'Model inputs'!C78 -> 516.02629 | N32: ='Model inputs'!N49*'Model inputs'!C78 -> 532.34419 | O32: ='Model inputs'!O49*'Model inputs'!C78 -> 547.35665 | P32: ='Model inputs'!P49*'Model inputs'!C78 -> 561.16812
A33: Stories delivered at month 6 (derived) · Verification and illustration policy: cost, margin and bar | C33: =SUM('Model inputs'!B31,'Model inputs'!B32) -> 1291.8938
A34: Stories delivered at month 6 (derived) · Month 6 reference (company, selected policy) | D34: =SUM('Model inputs'!B31,'Model inputs'!B32) -> 1291.8938
A35: Text and verification cost per story (USD, derived) | C35: ='Model inputs'!C45+'Model inputs'!C72*('Model inputs'!C46-'Model inputs'!C45) -> 0.01684
A36: Text and verification cost per story (USD, derived) > Sampled | C36: ='Model inputs'!C45+'Model inputs'!C73*('Model inputs'!C46-'Model inputs'!C45) -> 0.01684
A37: Text and verification cost per story (USD, derived) > Verify all | C37: ='Model inputs'!C45+'Model inputs'!C74*('Model inputs'!C46-'Model inputs'!C45) -> 0.0199
A38: Video cost per story (USD, derived) | C38: ='Model inputs'!C88*('Model inputs'!C71*'Model inputs'!C89*'Model inputs'!C90+'Model inputs'!C39) -> 0
A39: Clip check cost per clip (USD, two judges, estimate) | C39: =0.02 -> 0.02
A40: Cost input value | C40: 0
A41: Cost input value > Narration price per page | C41: =0.002 -> 0.002
...

Sheet Export notes
A1: Export notes
A2: These cells hold the value cfo.ai calculated instead of a formula. They do not recalculate when you edit an input.
A4: Sheet | B4: Cell | C4: Variable | D4: Period | E4: Scenario | F4: Why
A5: Model inputs | B5: C72 | C5: Share of gated uplift paid (derived) | E5: Main Scenario | F5: It reads Verification policy, which this workbook does not contain.
A6: Model inputs | B6: D128 | C6: Share of gated uplift paid (derived) | E6: Main Scenario | F6: It reads Verification policy, which this workbook does not contain.
